Workbook
Name imie: LUTY!$C$1
Name Kat: [1]Świadectwa!$N$18:$N$21
Name test: [1]Świadectwa!$P$26,[1]Świadectwa!$P$27,[1]Świadectwa!$Q$31,[1]Świadectwa!$Q$32,[1]Świadectwa!$R$23,[1]Świadectwa!$R$22

Sheet LISTOPAD (2)
A1: SG | D1: 44501 | E1: 44501 | F1: 44502 | G1: 44503 | H1: 44504 | I1: 44505 | J1: 44506 | K1: 44507 | L1: 44508 | M1: 44509 | N1: 44510 | O1: 44511 | P1: 44512 | Q1: 44513 | R1: 44514 | S1: 44515 | T1: 44516 | U1: 44517 | V1: 44518 | W1: 44519 | X1: 44520 | Y1: 44521 | Z1: 44522 | AA1: 44523 | AB1: 44524 | AC1: 44525 | AD1: 44526 | AE1: 44527 | AF1: 44528 | AG1: 44529 | AH1: 44530 | AK1: =20*8 -> 160 | AL1: Służba | AM1: Dyżur | AN1: inne | AO1: DT | AP1: zwolnienia
A2: SG212 | B2: D | C2: BORZĘCKI Tomasz | D2: =Zasoby!#REF! -> #REF! | F2: D | Z2: PS | AA2: S | AB2: S | AC2: S | AD2: PS | AJ2: =Tabela13[[#This Row],[FUNKCJONARIUSZ]] -> F-sz 001 | AK2: =D2+AL2+AM2+AN2-$AK$1+AO2+AP2 -> #REF! | AL2: =COUNTIF(E2:AI2,"D")*24+COUNTIF(E2:AI2,"12g")*12 -> 24 | AM2: =SUM(COUNTIF(E2:AI2,"k")+COUNTIF(E2:AI2,"s")+COUNTIF(E2:AI2,"wse"))*24+SUM(COUNTIF(E2:AI2,"Pk")+COUNTIF(E2:AI2,"Ps"))*12 -> 96 | AN2: =SUM(E2:AI2)+COUNTIF(E2:AI2,"uw")*8+COUNTIF(E2:AI2,"us")*8+COUNTIF(E2:AI2,"uz")*8 -> 0 | AO2: =COUNTIF(E2:AI2,"DT")*8 -> 0 | AP2: 0
A3: SG068 | B3: MP | C3: BUKOWSKI Bartosz | D3: =Zasoby!#REF! -> #REF! | E3: S | F3: PS | G3: - | H3: - | I3: - | J3: - | K3: - | L3: D | O3: D | AG3: PS | AH3: S | AJ3: =Tabela13[[#This Row],[FUNKCJONARIUSZ]] -> F-sz 002 | AK3: =D3+AL3+AM3+AN3-$AK$1+AO3+AP3 -> #REF! | AL3: =COUNTIF(E3:AI3,"D")*24+COUNTIF(E3:AI3,"12g")*12 -> 48 | AM3: =SUM(COUNTIF(E3:AI3,"k")+COUNTIF(E3:AI3,"s")+COUNTIF(E3:AI3,"wse"))*24+SUM(COUNTIF(E3:AI3,"Pk")+COUNTIF(E3:AI3,"Ps"))*12 -> 72 | AN3: =SUM(E3:AI3)+COUNTIF(E3:AI3,"uw")*8+COUNTIF(E3:AI3,"us")*8+COUNTIF(E3:AI3,"uz")*8 -> 0 | AO3: =COUNTIF(E3:AI3,"DT")*8 -> 0 | AP3: 0
A4: SG214 | B4: MP | C4: CHYŁA Katarzyna | D4: =Zasoby!#REF! -> #REF! | L4: ps | M4: s | N4: s | O4: s | P4: ps | AJ4: =Tabela13[[#This Row],[FUNKCJONARIUSZ]] -> F-sz 003 | AK4: =D4+AL4+AM4+AN4-$AK$1+AO4+AP4 -> #REF! | AL4: =COUNTIF(E4:AI4,"D")*24+COUNTIF(E4:AI4,"12g")*12 -> 0 | AM4: =SUM(COUNTIF(E4:AI4,"k")+COUNTIF(E4:AI4,"s")+COUNTIF(E4:AI4,"wse"))*24+SUM(COUNTIF(E4:AI4,"Pk")+COUNTIF(E4:AI4,"Ps"))*12 -> 96 | AN4: =SUM(E4:AI4)+COUNTIF(E4:AI4,"uw")*8+COUNTIF(E4:AI4,"us")*8+COUNTIF(E4:AI4,"uz")*8 -> 0 | AO4: =COUNTIF(E4:AI4,"DT")*8 -> 0 | AP4: 0
A5: SG068 | B5: MP | C5: DRGAS Kamil | D5: =Zasoby!#REF! -> #REF! | F5: ps | G5: s | H5: s | I5: ps | J5: - | K5: - | L5: - | M5: - | N5: D | R5: D | Z5: D | AJ5: =Tabela13[[#This Row],[FUNKCJONARIUSZ]] -> F-sz 004 | AK5: =D5+AL5+AM5+AN5-$AK$1+AO5+AP5 -> #REF! | AL5: =COUNTIF(E5:AI5,"D")*24+COUNTIF(E5:AI5,"12g")*12 -> 72 | AM5: =SUM(COUNTIF(E5:AI5,"k")+COUNTIF(E5:AI5,"s")+COUNTIF(E5:AI5,"wse"))*24+SUM(COUNTIF(E5:AI5,"Pk")+COUNTIF(E5:AI5,"Ps"))*12 -> 72 | AN5: =SUM(E5:AI5)+COUNTIF(E5:AI5,"uw")*8+COUNTIF(E5:AI5,"us")*8+COUNTIF(E5:AI5,"uz")*8 -> 0 | AO5: =COUNTIF(E5:AI5,"DT")*8 -> 0 | AP5: 0 | AQ5: D | AR5: służba | AS5: 24
A6: SG214 | B6: M | C6: GĄSIEWSKI Dariusz | D6: =Zasoby!#REF! -> #REF! | K6: D | S6: uw | T6: uw | U6: uw | V6: uw | AD6: PS | AE6: S | AF6: S | AG6: PS | AJ6: =Tabela13[[#This Row],[FUNKCJONARIUSZ]] -> F-sz 005 | AK6: =D6+AL6+AM6+AN6-$AK$1+AO6+AP6 -> #REF! | AL6: =COUNTIF(E6:AI6,"D")*24+COUNTIF(E6:AI6,"12g")*12 -> 24 | AM6: =SUM(COUNTIF(E6:AI6,"k")+COUNTIF(E6:AI6,"s")+COUNTIF(E6:AI6,"wse"))*24+SUM(COUNTIF(E6:AI6,"Pk")+COUNTIF(E6:AI6,"Ps"))*12 -> 72 | AN6: =SUM(E6:AI6)+COUNTIF(E6:AI6,"uw")*8+COUNTIF(E6:AI6,"us")*8+COUNTIF(E6:AI6,"uz")*8 -> 32 | AO6: =COUNTIF(E6:AI6,"DT")*8 -> 0 | AP6: 0 | AQ6: 12g | AR6: służba gazowiec | AS6: 12
A7: SG214 | B7: D | C7: GRZESIAK Sebastian | D7: =Zasoby!#REF! -> #REF! | I7: - | J7: - | K7: - | S7: ps | T7: s | U7: s | V7: s | W7: s | X7: s | Y7: s | Z7: ps | AJ7: =Tabela13[[#This Row],[FUNKCJONARIUSZ]] -> F-sz 006 | AK7: =D7+AL7+AM7+AN7-$AK$1+AO7+AP7 -> #REF! | AL7: =COUNTIF(E7:AI7,"D")*24+COUNTIF(E7:AI7,"12g")*12 -> 0 | AM7: =SUM(COUNTIF(E7:AI7,"k")+COUNTIF(E7:AI7,"s")+COUNTIF(E7:AI7,"wse"))*24+SUM(COUNTIF(E7:AI7,"Pk")+COUNTIF(E7:AI7,"Ps"))*12 -> 168 | AN7: =SUM(E7:AI7)+COUNTIF(E7:AI7,"uw")*8+COUNTIF(E7:AI7,"us")*8+COUNTIF(E7:AI7,"uz")*8 -> 0 | AO7: =COUNTIF(E7:AI7,"DT")*8 -> 0 | AP7: 0 | AQ7: ps | AR7: 1/2 dyżuru | AS7: 12
A8: SG214 | B8: D | C8: JAKIMIAK Marcin | D8: =Zasoby!#REF! -> #REF! | F8: PS | G8: S | H8: S | I8: S | J8: S | K8: S | L8: PS | AJ8: =Tabela13[[#This Row],[FUNKCJONARIUSZ]] -> F-sz 007 | AK8: =D8+AL8+AM8+AN8-$AK$1+AO8+AP8 -> #REF! | AL8: =COUNTIF(E8:AI8,"D")*24+COUNTIF(E8:AI8,"12g")*12 -> 0 | AM8: =SUM(COUNTIF(E8:AI8,"k")+COUNTIF(E8:AI8,"s")+COUNTIF(E8:AI8,"wse"))*24+SUM(COUNTIF(E8:AI8,"Pk")+COUNTIF(E8:AI8,"Ps"))*12 -> 144 | AN8: =SUM(E8:AI8)+COUNTIF(E8:AI8,"uw")*8+COUNTIF(E8:AI8,"us")*8+COUNTIF(E8:AI8,"uz")*8 -> 0 | AO8: =COUNTIF(E8:AI8,"DT")*8 -> 0 | AP8: 0 | AQ8: s | AR8: dyżur Ś-cie | AS8: 24
A9: SG214 | B9: D | C9: KALITA Mariusz | D9: =Zasoby!#REF! -> #REF! | E9: S | F9: PS | N9: uw | O9: - | P9: uw | AG9: PS | AH9: S | AJ9: =Tabela13[[#This Row],[FUNKCJONARIUSZ]] -> F-sz 008 | AK9: =D9+AL9+AM9+AN9-$AK$1+AO9+AP9 -> #REF! | AL9: =COUNTIF(E9:AI9,"D")*24+COUNTIF(E9:AI9,"12g")*12 -> 0 | AM9: =SUM(COUNTIF(E9:AI9,"k")+COUNTIF(E9:AI9,"s")+COUNTIF(E9:AI9,"wse"))*24+SUM(COUNTIF(E9:AI9,"Pk")+COUNTIF(E9:AI9,"Ps"))*12 -> 72 | AN9: =SUM(E9:AI9)+COUNTIF(E9:AI9,"uw")*8+COUNTIF(E9:AI9,"us")*8+COUNTIF(E9:AI9,"uz")*8 -> 16 | AO9: =COUNTIF(E9:AI9,"DT")*8 -> 0 | AP9: 0 | AQ9: us | AR9: urlop staż | AS9: 8
A10: SG212 | B10: M | C10: ŁUKACZ Sławomir | D10: =Zasoby!#REF! -> #REF! | F10: uw | G10: uw | H10: uw | I10: uw | J10: - | K10: - | L10: uw | M10: uw | Z10: PS | AA10: S | AB10: S | AC10: S | AD10: PS | AJ10: =Tabela13[[#This Row],[FUNKCJONARIUSZ]] -> F-sz 009 | AK10: =D10+AL10+AM10+AN10-$AK$1+AO10+AP10 -> #REF! | AL10: =COUNTIF(E10:AI10,"D")*24+COUNTIF(E10:AI10,"12g")*12 -> 0 | AM10: =SUM(COUNTIF(E10:AI10,"k")+COUNTIF(E10:AI10,"s")+COUNTIF(E10:AI10,"wse"))*24+SUM(COUNTIF(E10:AI10,"Pk")+COUNTIF(E10:AI10,"Ps"))*12 -> 96 | AN10: =SUM(E10:AI10)+COUNTIF(E10:AI10,"uw")*8+COUNTIF(E10:AI10,"us")*8+COUNTIF(E10:AI10,"uz")*8 -> 48 | AO10: =COUNTIF(E10:AI10,"DT")*8 -> 0 | AP10: 0 | AQ10: uw | AR10: urlop wypoczynkowy | AS10: 8
A11: SG212 | B11: M | C11: MIZGIER Bartosz | D11: =Zasoby!#REF! -> #REF! | E11: S | F11: PS | W11: PS | X11: S | Y11: S | Z11: PS | AG11: PS | AH11: S | AJ11: =Tabela13[[#This Row],[FUNKCJONARIUSZ]] -> F-sz 010 | AK11: =D11+AL11+AM11+AN11-$AK$1+AO11+AP11 -> #REF! | AL11: =COUNTIF(E11:AI11,"D")*24+COUNTIF(E11:AI11,"12g")*12 -> 0 | AM11: =SUM(COUNTIF(E11:AI11,"k")+COUNTIF(E11:AI11,"s")+COUNTIF(E11:AI11,"wse"))*24+SUM(COUNTIF(E11:AI11,"Pk")+COUNTIF(E11:AI11,"Ps"))*12 -> 144 | AN11: =SUM(E11:AI11)+COUNTIF(E11:AI11,"uw")*8+COUNTIF(E11:AI11,"us")*8+COUNTIF(E11:AI11,"uz")*8 -> 0 | AO11: =COUNTIF(E11:AI11,"DT")*8 -> 0 | AP11: 0 | AQ11: uz | AR11: urlop zaległy | AS11: 8
A12: SG070 | B12: MP | C12: MŁYŃSKI Błażej | D12: =Zasoby!#REF! -> #REF! | J12: D | S12: PS | T12: S | U12: S | V12: S | W12: PS | AJ12: =Tabela13[[#This Row],[FUNKCJONARIUSZ]] -> F-sz 011 | AK12: =D12+AL12+AM12+AN12-$AK$1+AO12+AP12 -> #REF! | AL12: =COUNTIF(E12:AI12,"D")*24+COUNTIF(E12:AI12,"12g")*12 -> 24 | AM12: =SUM(COUNTIF(E12:AI12,"k")+COUNTIF(E12:AI12,"s")+COUNTIF(E12:AI12,"wse"))*24+SUM(COUNTIF(E12:AI12,"Pk")+COUNTIF(E12:AI12,"Ps"))*12 -> 96 | AO12: =COUNTIF(E12:AI12,"DT")*8 -> 0 | AP12: 0 | AQ12: pk | AR12: 1/2 dyżuru | AS12: 12
A13: SG212 | B13: ZD | C13: MOSKALONEK Hubert | D13: =Zasoby!#REF! -> #REF! | F13: ps | G13: s | H13: s | I13: s | J13: s | K13: s | L13: ps | M13: - | N13: - | O13: - | P13: - | Q13: - | R13: - | S13: - | W13: PS | X13: S | Y13: S | Z13: PS | AA13: - | AB13: - | AC13: - | AD13: - | AE13: D | AH13: D | AJ13: =Tabela13[[#This Row],[FUNKCJONARIUSZ]] -> F-sz 012 | AK13: =D13+AL13+AM13+AN13-$AK$1+AO13+AP13 -> #REF! | AL13: =COUNTIF(E13:AI13,"D")*24+COUNTIF(E13:AI13,"12g")*12 -> 48 | AM13: =SUM(COUNTIF(E13:AI13,"k")+COUNTIF(E13:AI13,"s")+COUNTIF(E13:AI13,"wse"))*24+SUM(COUNTIF(E13:AI13,"Pk")+COUNTIF(E13:AI13,"Ps"))*12 -> 216 | AN13: =SUM(E13:AI13)+COUNTIF(E13:AI13,"uw")*8+COUNTIF(E13:AI13,"us")*8+COUNTIF(E13:AI13,"uz")*8 -> 0 | AO13: =COUNTIF(E13:AI13,"DT")*8 -> 0 | AP13: 0 | AQ13: k | AR13: dyżur K-g | AS13: 24
A14: SG070 | B14: D | C14: NOWICKI Radosław | D14: =Zasoby!#REF! -> #REF! | G14: D | S14: PS | T14: S | U14: S | V14: S | W14: PS | AC14: D | AJ14: =Tabela13[[#This Row],[FUNKCJONARIUSZ]] -> F-sz 013 | AK14: =D14+AL14+AM14+AN14-$AK$1+AO14+AP14 -> #REF! | AL14: =COUNTIF(E14:AI14,"D")*24+COUNTIF(E14:AI14,"12g")*12 -> 48 | AM14: =SUM(COUNTIF(E14:AI14,"k")+COUNTIF(E14:AI14,"s")+COUNTIF(E14:AI14,"wse"))*24+SUM(COUNTIF(E14:AI14,"Pk")+COUNTIF(E14:AI14,"Ps"))*12 -> 96 | AN14: =SUM(E14:AI14)+COUNTIF(E14:AI14,"uw")*8+COUNTIF(E14:AI14,"us")*8+COUNTIF(E14:AI14,"uz")*8 -> 0 | AO14: =COUNTIF(E14:AI14,"DT")*8 -> 0 | AP14: 0 | AQ14: wse | AR14: WSE | AS14: 24
A15: SG212 | B15: ZD | C15: PALUCH Łukasz | D15: =Zasoby!#REF! -> #REF! | L15: PS | M15: S | N15: S | O15: S | P15: PS | AB15: D | AJ15: =Tabela13[[#This Row],[FUNKCJONARIUSZ]] -> F-sz 014 | AK15: =D15+AL15+AM15+AN15-$AK$1+AO15+AP15 -> #REF! | AL15: =COUNTIF(E15:AI15,"D")*24+COUNTIF(E15:AI15,"12g")*12 -> 24 | AM15: =SUM(COUNTIF(E15:AI15,"k")+COUNTIF(E15:AI15,"s")+COUNTIF(E15:AI15,"wse"))*24+SUM(COUNTIF(E15:AI15,"Pk")+COUNTIF(E15:AI15,"Ps"))*12 -> 96 | AN15: =SUM(E15:AI15)+COUNTIF(E15:AI15,"uw")*8+COUNTIF(E15:AI15,"us")*8+COUNTIF(E15:AI15,"uz")*8 -> 0 | AO15: =COUNTIF(E15:AI15,"DT")*8 -> 0 | AP15: 0 | AQ15: l4 | AR15: Zwolnienia lekarskie | AS15: ?
A16: SG070 | B16: MP | C16: PRYCA Adam | D16: =Zasoby!#REF! -> #REF! | W16: D | Z16: PS | AA16: S | AB16: S | AC16: S | AD16: PS | AJ16: =Tabela13[[#This Row],[FUNKCJONARIUSZ]] -> F-sz 015 | AK16: =D16+AL16+AM16+AN16-$AK$1+AO16+AP16 -> #REF! | AL16: =COUNTIF(E16:AI16,"D")*24+COUNTIF(E16:AI16,"12g")*12 -> 24 | AM16: =SUM(COUNTIF(E16:AI16,"k")+COUNTIF(E16:AI16,"s")+COUNTIF(E16:AI16,"wse"))*24+SUM(COUNTIF(E16:AI16,"Pk")+COUNTIF(E16:AI16,"Ps"))*12 -> 96 | AN16: =SUM(E16:AI16)+COUNTIF(E16:AI16,"uw")*8+COUNTIF(E16:AI16,"us")*8+COUNTIF(E16:AI16,"uz")*8 -> 0 | AO16: =COUNTIF(E16:AI16,"DT")*8 -> 0 | AP16: 0
A17: SG007 | B17: MP | C17: SAJDAK Patryk | D17: =Zasoby!#REF! -> #REF! | E17: D | H17: uw | I17: uw | T17: D | X17: D | AJ17: =Tabela13[[#This Row],[FUNKCJONARIUSZ]] -> F-sz 016 | AK17: =D17+AL17+AM17+AN17-$AK$1+AO17+AP17 -> #REF! | AL17: =COUNTIF(E17:AI17,"D")*24+COUNTIF(E17:AI17,"12g")*12 -> 72 | AM17: =SUM(COUNTIF(E17:AI17,"k")+COUNTIF(E17:AI17,"s")+COUNTIF(E17:AI17,"wse"))*24+SUM(COUNTIF(E17:AI17,"Pk")+COUNTIF(E17:AI17,"Ps"))*12 -> 0 | AN17: =SUM(E17:AI17)+COUNTIF(E17:AI17,"uw")*8+COUNTIF(E17:AI17,"us")*8+COUNTIF(E17:AI17,"uz")*8 -> 16 | AO17: =COUNTIF(E17:AI17,"DT")*8 -> 0 | AP17: 0
A18: SG214 | B18: M | C18: SPRUTTA Radosław | D18: =Zasoby!#REF! -> #REF! | E18: - | F18: uw | G18: uw | L18: PS | M18: S | N18: S | O18: S | P18: PS | AJ18: =Tabela13[[#This Row],[FUNKCJONARIUSZ]] -> F-sz 017 | AK18: =D18+AL18+AM18+AN18-$AK$1+AO18+AP18 -> #REF! | AL18: =COUNTIF(E18:AI18,"D")*24+COUNTIF(E18:AI18,"12g")*12 -> 0 | AM18: =SUM(COUNTIF(E18:AI18,"k")+COUNTIF(E18:AI18,"s")+COUNTIF(E18:AI18,"wse"))*24+SUM(COUNTIF(E18:AI18,"Pk")+COUNTIF(E18:AI18,"Ps"))*12 -> 96 | AN18: =SUM(E18:AI18)+COUNTIF(E18:AI18,"uw")*8+COUNTIF(E18:AI18,"us")*8+COUNTIF(E18:AI18,"uz")*8 -> 16 | AO18: =COUNTIF(E18:AI18,"DT")*8 -> 0 | AP18: 0
A19: SG070 | B19: D | C19: STRANC Andrzej | D19: =Zasoby!#REF! -> #REF! | I19: D | Z19: PS | AA19: S | AB19: S | AC19: S | AD19: S | AE19: S | AF19: S | AG19: PS | AJ19: =Tabela13[[#This Row],[FUNKCJONARIUSZ]] -> F-sz 018 | AK19: =D19+AL19+AM19+AN19-$AK$1+AO19+AP19 -> #REF! | AL19: =COUNTIF(E19:AI19,"D")*24+COUNTIF(E19:AI19,"12g")*12 -> 24 | AM19: =SUM(COUNTIF(E19:AI19,"k")+COUNTIF(E19:AI19,"s")+COUNTIF(E19:AI19,"wse"))*24+SUM(COUNTIF(E19:AI19,"Pk")+COUNTIF(E19:AI19,"Ps"))*12 -> 168 | AN19: =SUM(E19:AI19)+COUNTIF(E19:AI19,"uw")*8+COUNTIF(E19:AI19,"us")*8+COUNTIF(E19:AI19,"uz")*8 -> 0 | AO19: =COUNTIF(E19:AI19,"DT")*8 -> 0 | AP19: 0
A20: SG212 | B20: D | C20: SZCZEPANIAK Zbigniew | D20: =Zasoby!#REF! -> #REF! | H20: D | AD20: PS | AE20: S | AF20: S | AG20: PS | AJ20: =Tabela13[[#This Row],[FUNKCJONARIUSZ]] -> F-sz 019 | AK20: =D20+AL20+AM20+AN20-$AK$1+AO20+AP20 -> #REF! | AL20: =COUNTIF(E20:AI20,"D")*24+COUNTIF(E20:AI20,"12g")*12 -> 24 | AM20: =SUM(COUNTIF(E20:AI20,"k")+COUNTIF(E20:AI20,"s")+COUNTIF(E20:AI20,"wse"))*24+SUM(COUNTIF(E20:AI20,"Pk")+COUNTIF(E20:AI20,"Ps"))*12 -> 72 | AN20: =SUM(E20:AI20)+COUNTIF(E20:AI20,"uw")*8+COUNTIF(E20:AI20,"us")*8+COUNTIF(E20:AI20,"uz")*8 -> 0 | AO20: =COUNTIF(E20:AI20,"DT")*8 -> 0 | AP20: 0
A21: SG214 | B21: ZD | C21: SZYMAŃSKI Tomasz Paweł | D21: =Zasoby!#REF! -> #REF! | E21: S | F21: PS | U21: D | AG21: PS | AH21: S | AJ21: =Tabela13[[#This Row],[FUNKCJONARIUSZ]] -> F-sz 020 | AK21: =D21+AL21+AM21+AN21-$AK$1+AO21+AP21 -> #REF! | AL21: =COUNTIF(E21:AI21,"D")*24+COUNTIF(E21:AI21,"12g")*12 -> 24 | AM21: =SUM(COUNTIF(E21:AI21,"k")+COUNTIF(E21:AI21,"s")+COUNTIF(E21:AI21,"wse"))*24+SUM(COUNTIF(E21:AI21,"Pk")+COUNTIF(E21:AI21,"Ps"))*12 -> 72 | AN21: =SUM(E21:AI21)+COUNTIF(E21:AI21,"uw")*8+COUNTIF(E21:AI21,"us")*8+COUNTIF(E21:AI21,"uz")*8 -> 0 | AO21: =COUNTIF(E21:AI21,"DT")*8 -> 0 | AP21: 0
A22: SG212 | B22: D | C22: ŚWIREPO Piotr | D22: =Zasoby!#REF! -> #REF! | E22: - | F22: - | G22: - | H22: - | I22: - | J22: - | K22: - | L22: PS | M22: S | N22: S | O22: S | P22: S | Q22: S | R22: S | S22: PS | AJ22: =Tabela13[[#This Row],[FUNKCJONARIUSZ]] -> F-sz 021 | AK22: =D22+AL22+AM22+AN22-$AK$1+AO22+AP22 -> #REF! | AL22: =COUNTIF(E22:AI22,"D")*24+COUNTIF(E22:AI22,"12g")*12 -> 0 | AM22: =SUM(COUNTIF(E22:AI22,"k")+COUNTIF(E22:AI22,"s")+COUNTIF(E22:AI22,"wse"))*24+SUM(COUNTIF(E22:AI22,"Pk")+COUNTIF(E22:AI22,"Ps"))*12 -> 168 | AN22: =SUM(E22:AI22)+COUNTIF(E22:AI22,"uw")*8+COUNTIF(E22:AI22,"us")*8+COUNTIF(E22:AI22,"uz")*8 -> 0 | AO22: =COUNTIF(E22:AI22,"DT")*8 -> 0 | AP22: 0
A23: SG068 | B23: MP | C23: WALCZAK Oskar | D23: =Zasoby!#REF! -> #REF! | F23: uw | G23: uw | H23: uw | I23: uw | L23: uw | M23: d | P23: d | S23: d | V23: d | Y23: D | AD23: D | AG23: D | AJ23: =Tabela13[[#This Row],[FUNKCJONARIUSZ]] -> F-sz 022 | AK23: =D23+AL23+AM23+AN23-$AK$1+AO23+AP23 -> #REF! | AL23: =COUNTIF(E23:AI23,"D")*24+COUNTIF(E23:AI23,"12g")*12 -> 168 | AM23: =SUM(COUNTIF(E23:AI23,"k")+COUNTIF(E23:AI23,"s")+COUNTIF(E23:AI23,"wse"))*24+SUM(COUNTIF(E23:AI23,"Pk")+COUNTIF(E23:AI23,"Ps"))*12 -> 0 | AN23: =SUM(E23:AI23)+COUNTIF(E23:AI23,"uw")*8+COUNTIF(E23:AI23,"us")*8+COUNTIF(E23:AI23,"uz")*8 -> 40 | AO23: =COUNTIF(E23:AI23,"DT")*8 -> 0 | AP23: 0
A24: SG214 | B24: ZD | C24: WALKOWIAK Wojciech | D24: =Zasoby!#REF! -> #REF! | F24: uw | G24: uw | H24: uw | I24: uw | J24: - | K24: - | L24: uw | N24: uw | O24: - | P24: uw | AJ24: =Tabela13[[#This Row],[FUNKCJONARIUSZ]] -> F-sz 023 | AK24: =D24+AL24+AM24+AN24-$AK$1+AO24+AP24 -> #REF! | AL24: =COUNTIF(E24:AI24,"D")*24+COUNTIF(E24:AI24,"12g")*12 -> 0 | AM24: =SUM(COUNTIF(E24:AI24,"k")+COUNTIF(E24:AI24,"s")+COUNTIF(E24:AI24,"wse"))*24+SUM(COUNTIF(E24:AI24,"Pk")+COUNTIF(E24:AI24,"Ps"))*12 -> 0 | AN24: =SUM(E24:AI24)+COUNTIF(E24:AI24,"uw")*8+COUNTIF(E24:AI24,"us")*8+COUNTIF(E24:AI24,"uz")*8 -> 56 | AO24: =COUNTIF(E24:AI24,"DT")*8 -> 0 | AP24: 0
A25: SG068 | B25: D | C25: WERSZNER Piotr | D25: =Zasoby!#REF! -> #REF! | F25: uw | G25: uw | H25: uw | I25: uw | J25: - | K25: - | L25: uw | M25: uw | N25: uw | Q25: D | AA25: D | AF25: D | AJ25: =Tabela13[[#This Row],[FUNKCJONARIUSZ]] -> F-sz 024 | AK25: =D25+AL25+AM25+AN25-$AK$1+AO25+AP25 -> #REF! | AL25: =COUNTIF(E25:AI25,"D")*24+COUNTIF(E25:AI25,"12g")*12 -> 72 | AM25: =SUM(COUNTIF(E25:AI25,"k")+COUNTIF(E25:AI25,"s")+COUNTIF(E25:AI25,"wse"))*24+SUM(COUNTIF(E25:AI25,"Pk")+COUNTIF(E25:AI25,"Ps"))*12 -> 0 | AN25: =SUM(E25:AI25)+COUNTIF(E25:AI25,"uw")*8+COUNTIF(E25:AI25,"us")*8+COUNTIF(E25:AI25,"uz")*8 -> 56 | AO25: =COUNTIF(E25:AI25,"DT")*8 -> 0 | AP25: 0
A26: SG068 | B26: M | C26: WITWICKI Adrian | D26: =Zasoby!#REF! -> #REF! | F26: PS | G26: S | H26: S | I26: S | J26: S | K26: S | L26: PS | AJ26: =Tabela13[[#This Row],[FUNKCJONARIUSZ]] -> F-sz 025 | AK26: =D26+AL26+AM26+AN26-$AK$1+AO26+AP26 -> #REF! | AL26: =COUNTIF(E26:AI26,"D")*24+COUNTIF(E26:AI26,"12g")*12 -> 0 | AM26: =SUM(COUNTIF(E26:AI26,"k")+COUNTIF(E26:AI26,"s")+COUNTIF(E26:AI26,"wse"))*24+SUM(COUNTIF(E26:AI26,"Pk")+COUNTIF(E26:AI26,"Ps"))*12 -> 144 | AN26: =SUM(E26:AI26)+COUNTIF(E26:AI26,"uw")*8+COUNTIF(E26:AI26,"us")*8+COUNTIF(E26:AI26,"uz")*8 -> 0 | AO26: =COUNTIF(E26:AI26,"DT")*8 -> 0 | AP26: 0
A27: SG212 | B27: ZD | C27: ZAJĄC Rafał | D27: =Zasoby!#REF! -> #REF! | F27: uw | G27: uw | H27: uw | I27: uw | J27: - | K27: - | L27: uw | M27: uw | N27: uw | O27: - | P27: uw | Q27: - | R27: - | S27: uw | T27: uw | U27: uw | V27: uw | W27: uw | AJ27: =Tabela13[[#This Row],[FUNKCJONARIUSZ]] -> F-sz 026 | AK27: 38 | AL27: =COUNTIF(E27:AI27,"D")*24+COUNTIF(E27:AI27,"12g")*12 -> 0 | AM27: =SUM(COUNTIF(E27:AI27,"k")+COUNTIF(E27:AI27,"s")+COUNTIF(E27:AI27,"wse"))*24+SUM(COUNTIF(E27:AI27,"Pk")+COUNTIF(E27:AI27,"Ps"))*12 -> 0 | AN27: =SUM(E27:AI27)+COUNTIF(E27:AI27,"uw")*8+COUNTIF(E27:AI27,"us")*8+COUNTIF(E27:AI27,"uz")*8 -> 104 | AO27: =COUNTIF(E27:AI27,"DT")*8 -> 0 | AP27: 0
A28: SG007 | B28: D | C28: ZATWARNICKA Joanna | D28: =Zasoby!#REF! -> #REF! | P28: PS | Q28: S | R28: S | S28: PS | AJ28: =Tabela13[[#This Row],[FUNKCJONARIUSZ]] -> F-sz 027 | AK28: =D28+AL28+AM28+AN28-$AK$1+AO28+AP28 -> #REF! | AL28: =COUNTIF(E28:AI28,"D")*24+COUNTIF(E28:AI28,"12g")*12 -> 0 | AM28: =SUM(COUNTIF(E28:AI28,"k")+COUNTIF(E28:AI28,"s")+COUNTIF(E28:AI28,"wse"))*24+SUM(COUNTIF(E28:AI28,"Pk")+COUNTIF(E28:AI28,"Ps"))*12 -> 72 | AN28: =SUM(E28:AI28)+COUNTIF(E28:AI28,"uw")*8+COUNTIF(E28:AI28,"us")*8+COUNTIF(E28:AI28,"uz")*8 -> 0 | AO28: =COUNTIF(E28:AI28,"DT")*8 -> 0 | AP28: 0
A29: SG212 | B29: M | C29: ZEMBRZUSKI Krzysztof | D29: =Zasoby!#REF! -> #REF! | E29: - | F29: uw | G29: uw | H29: uw | I29: uw | J29: - | K29: - | L29: uw | M29: uw | N29: uw | O29: - | P29: uw | S29: uw | T29: uw | U29: uw | V29: uw | W29: uw | X29: - | Y29: - | Z29: uw | AA29: uw | AB29: uw | AC29: uw | AD29: uw | AE29: - | AF29: - | AG29: uw | AH29: uw | AJ29: =Tabela13[[#This Row],[FUNKCJONARIUSZ]] -> F-sz 028 | AK29: =D29+AL29+AM29+AN29-$AK$1+AO29+AP29 -> #REF! | AL29: =COUNTIF(E29:AI29,"D")*24+COUNTIF(E29:AI29,"12g")*12 -> 0 | AM29: =SUM(COUNTIF(E29:AI29,"k")+COUNTIF(E29:AI29,"s")+COUNTIF(E29:AI29,"wse"))*24+SUM(COUNTIF(E29:AI29,"Pk")+COUNTIF(E29:AI29,"Ps"))*12 -> 0 | AN29: =SUM(E29:AI29)+COUNTIF(E29:AI29,"uw")*8+COUNTIF(E29:AI29,"us")*8+COUNTIF(E29:AI29,"uz")*8 -> 160 | AO29: =COUNTIF(E29:AI29,"DT")*8 -> 0 | AP29: 0
C31: SŁUŻBA Ś-CIE | E31: =COUNTIF(E2:E29,"D") -> 1 | F31: =COUNTIF(F2:F29,"D") -> 1 | G31: =COUNTIF(G2:G29,"D") -> 1 | H31: =COUNTIF(H2:H29,"D") -> 1 | I31: =COUNTIF(I2:I29,"D") -> 1 | J31: =COUNTIF(J2:J29,"D") -> 1 | K31: =COUNTIF(K2:K29,"D") -> 1 | L31: =COUNTIF(L2:L29,"D") -> 1 | ... AI31: =COUNTIF(AI2:AI29,"D") -> 0
C32: SŁUŻBA K-G | E32: =COUNTIF(E48:E101,"D")+COUNTIF(E48:E101,"w") -> 0 | F32: =COUNTIF(F48:F101,"D")+COUNTIF(F48:F101,"w") -> 0 | G32: =COUNTIF(G48:G101,"D")+COUNTIF(G48:G101,"w") -> 0 | H32: =COUNTIF(H48:H101,"D")+COUNTIF(H48:H101,"w") -> 0 | I32: =COUNTIF(I48:I101,"D")+COUNTIF(I48:I101,"w") -> 0 | J32: =COUNTIF(J48:J101,"D")+COUNTIF(J48:J101,"w") -> 0 | K32: =COUNTIF(K48:K101,"D")+COUNTIF(K48:K101,"w") -> 0 | L32: =COUNTIF(L48:L101,"D")+COUNTIF(L48:L101,"w") -> 0 | ... AI32: =COUNTIF(AI48:AI101,"D")+COUNTIF(AI48:AI101,"w") -> 0
C33: DYŻUR Ś-CIE | E33: =COUNTIF(E2:E29,"S")+COUNTIF(E49:E101,"S") -> 4 | F33: =COUNTIF(F2:F29,"S")+COUNTIF(F49:F101,"S") -> 0 | G33: =COUNTIF(G2:G29,"S")+COUNTIF(G49:G101,"S") -> 4 | H33: =COUNTIF(H2:H29,"S")+COUNTIF(H49:H101,"S") -> 4 | I33: =COUNTIF(I2:I29,"S")+COUNTIF(I49:I101,"S") -> 3 | J33: =COUNTIF(J2:J29,"S")+COUNTIF(J49:J101,"S") -> 4 | K33: =COUNTIF(K2:K29,"S")+COUNTIF(K49:K101,"S") -> 4 | L33: =COUNTIF(L2:L29,"S")+COUNTIF(L49:L101,"S") -> 0 | ... AI33: =COUNTIF(AI2:AI29,"S")+COUNTIF(AI49:AI101,"S") -> 0
C34: DYŻUR K-G | E34: =COUNTIF(E2:E31,"K")+COUNTIF(E48:E102,"K") -> 4 | F34: =COUNTIF(F2:F31,"K")+COUNTIF(F48:F102,"K") -> 0 | G34: =COUNTIF(G2:G31,"K")+COUNTIF(G48:G102,"K") -> 3 | H34: =COUNTIF(H2:H31,"K")+COUNTIF(H48:H102,"K") -> 4 | I34: =COUNTIF(I2:I31,"K")+COUNTIF(I48:I102,"K") -> 2 | J34: =COUNTIF(J2:J31,"K")+COUNTIF(J48:J102,"K") -> 4 | K34: =COUNTIF(K2:K31,"K")+COUNTIF(K48:K102,"K") -> 4 | L34: =COUNTIF(L2:L31,"K")+COUNTIF(L48:L102,"K") -> 4 | ... AJ34: =COUNTIF(AJ2:AJ31,"K")+COUNTIF(AJ48:AJ102,"K") -> 0
C36: DYŻUR Ś-CIE | F36: JAKIMIAK | J36: JAKIMIAK | M36: ŚWIREPO | Q36: ŚWIREPO | T36: GRZESIAK | X36: GRZESIAK | AA36: BORZĘCKI | AE36: SZCZECPANIAK | AH36: KALITA
F37: MOSKALONEK | J37: MOSKALONEK | M37: PALUCH | Q37: ZATWARNICKA | T37: NOWICKI | X37: MOSKALONEK | AA37: STRANC | AE37: STRANC | AH37: SZYMAŃSKI
F38: WITWICKI | J38: WITWICKI | M38: SPRUTTA | Q38: ŁUSZCZYŃSKI | T38: CHUDZIAK | X38: MIZGIER | AA38: ŁUKACZ | AE38: GĄSIEWSKI | AH38: MIZGIER
F39: DRGAS | J39: SZCZEPAŃSKI | M39: CHYŁA | Q39: PEZAŁA | T39: MŁYŃSKI | X39: WOŹNIAK | AA39: PRYCA | AE39: MAŁKOWSKI | AH39: BUKOWSKI
C41: DYŻUR K-G
A47: SG | E47: =E1 -> 44501 | F47: =F1 -> 44502 | G47: =G1 -> 44503 | H47: =H1 -> 44504 | I47: =I1 -> 44505 | J47: =J1 -> 44506 | K47: =K1 -> 44507 | L47: =L1 -> 44508 | ... AH47: =AH1 -> 44530 | AJ47: 44440 | AK47: 168 | AL47: Służba | AM47: Dyżur | AN47: inne | AO47: DT | AP47: zwolnienia
A48: SG312 | B48: ZD | C48: BARAN Marek | D48: =#REF! -> #REF! | F48: PK | G48: K | H48: K | I48: PK | AJ48: =C48 -> BARAN Marek | AK48: =D48+AL48+AM48+AN48-$AK$47+AO48+AP48 -> #REF! | AL48: =COUNTIF(E48:AI48,"D")*24+COUNTIF(E48:AI48,"12g")*12+COUNTIF(E48:AI48,"w")*24 -> 0 | AM48: =SUM(COUNTIF(E48:AI48,"k")+COUNTIF(E48:AI48,"s")+COUNTIF(E48:AI48,"wse"))*24+SUM(COUNTIF(E48:AI48,"Pk")+COUNTIF(E48:AI48,"Ps"))*12 -> 72 | AN48: =SUM(E48:AI48)+COUNTIF(E48:AI48,"uw")*8+COUNTIF(E48:AI48,"us")*8+COUNTIF(E48:AI48,"uz")*8 -> 0 | AO48: =COUNTIF(E48:AI48,"DT")*8 -> 0
...

Sheet Swiadectwa
A1: Id | B1: Marynarze | C1: Stanowiska | D1: Jednostka
A2: 1 | B2: F-sz 001 | C2: Mar. pokładowy | D2: KAT II
A3: 1 | B3: F-sz 001 | C3: ZD pokład pokład. | D3: KAT II
A4: 1 | B4: F-sz 001 | C4: Dowódca | D4: KAT II
A5: 1 | B5: F-sz 001 | C5: Dowódca | D5: KAT III
A6: 1 | B6: F-sz 001 | C6: Dowódca | D6: KAT IV
A7: 2 | B7: F-sz 002 | C7: Mar. pokładowy | D7: KAT IV
A8: 2 | B8: F-sz 002 | C8: Motorzysta | D8: KAT IV
A9: 2 | B9: F-sz 002 | C9: Mar. pokładowy | D9: KAT II
A10: 2 | B10: F-sz 002 | C10: Mar. pokładowy | D10: KAT III
A11: 2 | B11: F-sz 002 | C11: Artylerzysta | D11: KAT III
A12: 2 | B12: F-sz 002 | C12: Dowódca | D12: KAT IV
A13: 3 | B13: F-sz 003 | C13: Mar. pokładowy | D13: KAT II
... A157: 31 | B157: F-sz 031 | C157: Elektryk | D157: KAT III
A367: Anulowany
A381: 21.03.19r.
A397: Anulowany
A423: 21.03.19r.

Sheet Jednostki
A1: KAT II | B1: KAT III | C1: KAT IV
A2: SG212 | B2: SG112 | C2: SG006
A3: SG214 | C3: SG007
C4: SG046
C5: SG068
C6: SG070

Sheet Zalogi
A1: KAT II | B1: KAT III | C1: KAT IV
A2: Dowódca | B2: Dowódca | C2: Dowódca
A3: Zastępca dowódcy | B3: Zastępca dowódcy | C3: Bosman
A4: Mechanik | B4: Mechanik | C4: Motorzysta
A5: Marynarz pokładowy | B5: Elektryk | C5: Marynarz pokładowy
B6: Marynarz pokładowy
B7: Artylerzysta

Sheet Zasoby
B1: FUNKCJONARIUSZ | C1: Listopad | D1: Grudzień | E1: Koniec roku | G1: Stopień
A2: 1 | B2: F-sz 001 | C2: =LISTOPAD!AK2 -> -80.5 | D2: =GRUDZIEŃ!D2 -> -80.5 | E2: =GRUDZIEŃ!AK2 -> -132.5 | G2: chor.
A3: 2 | B3: F-sz 002 | C3: =LISTOPAD!AK3 -> -67 | D3: =GRUDZIEŃ!D3 -> -67 | E3: =GRUDZIEŃ!AK3 -> -59 | G3: bsm.
A4: 3 | B4: F-sz 003 | C4: =LISTOPAD!AK4 -> -69 | D4: =GRUDZIEŃ!D4 -> -69 | E4: =GRUDZIEŃ!AK4 -> -85 | G4: kpr.
A5: 4 | B5: F-sz 004 | C5: =LISTOPAD!AK5 -> -46 | D5: =GRUDZIEŃ!D5 -> -46 | E5: =GRUDZIEŃ!AK5 -> -50 | G5: bsm.
A6: 5 | B6: F-sz 005 | C6: =LISTOPAD!AK6 -> -29.5 | D6: =GRUDZIEŃ!D6 -> -29.5 | E6: =GRUDZIEŃ!AK6 -> -13.5 | G6: por.
A7: 6 | B7: F-sz 006 | C7: =LISTOPAD!AK7 -> -22 | D7: =GRUDZIEŃ!D7 -> -22 | E7: =GRUDZIEŃ!AK7 -> -62 | G7: chor.
A8: 7 | B8: F-sz 007 | C8: =LISTOPAD!AK8 -> 174 | D8: =GRUDZIEŃ!D8 -> 174 | E8: =GRUDZIEŃ!AK8 -> -10 | G8: chor.
A9: 8 | B9: F-sz 008 | C9: =LISTOPAD!AK9 -> -8 | D9: =GRUDZIEŃ!D9 -> -8 | E9: =GRUDZIEŃ!AK9 -> -36 | G9: kpt.
A10: 9 | B10: F-sz 009 | C10: =LISTOPAD!AK10 -> 115 | D10: =GRUDZIEŃ!D10 -> 115 | E10: =GRUDZIEŃ!AK10 -> 39 | G10: chor.
A11: 10 | B11: F-sz 010 | C11: =LISTOPAD!AK11 -> 84.5 | D11: =GRUDZIEŃ!D11 -> 84.5 | E11: =GRUDZIEŃ!AK11 -> 68.5 | G11: chor.
A12: 11 | B12: F-sz 011 | C12: =LISTOPAD!AK12 -> 122 | D12: =GRUDZIEŃ!D12 -> 122 | E12: =GRUDZIEŃ!AK12 -> -62 | G12: bsm.
A13: 12 | B13: F-sz 012 | C13: =LISTOPAD!AK13 -> 71 | D13: =GRUDZIEŃ!D13 -> 71 | E13: =GRUDZIEŃ!AK13 -> 55 | G13: chor.
... A29: 29 | B29: F-sz 028 | C29: =LISTOPAD!AK29 -> 42.5 | D29: =GRUDZIEŃ!D29 -> 42.5 | E29: =GRUDZIEŃ!AK29 -> 26.5 | G29: chor.

Sheet KAT II
B1: Dowódca | C1: Z-ca dowódcy | D1: Oficer Mechanik | E1: Mar.pokł
B2: F-sz 001 | C2: F-sz 001 | D2: F-sz 005 | E2: F-sz 001
B3: F-sz 006 | C3: F-sz 006 | D3: F-sz 010 | E3: F-sz 002
B4: F-sz 007 | C4: F-sz 007 | D4: F-sz 013 | E4: F-sz 003
B5: F-sz 009 | C5: F-sz 009 | D5: F-sz 015 | E5: F-sz 005
B6: F-sz 015 | C6: F-sz 015 | D6: F-sz 020 | E6: F-sz 006
B7: F-sz 017 | C7: F-sz 016 | D7: F-sz 028 | E7: F-sz 007
B8: F-sz 022 | C8: F-sz 017 | D8: F-sz 031 | E8: F-sz 013
B9: F-sz 024 | C9: F-sz 021 | E9: F-sz 014
B10: F-sz 026 | C10: F-sz 022 | E10: F-sz 015
C11: F-sz 023 | E11: F-sz 016
C12: F-sz 024 | E12: F-sz 017
C13: F-sz 026 | E13: F-sz 018
C14: F-sz 027 | E14: F-sz 019
C15: F-sz 029 | E15: F-sz 021
C16: F-sz 031 | E16: F-sz 023
E17: F-sz 026
E18: F-sz 028
E19: F-sz 031

Sheet KAT III
A1: Dowódca | B1: Z-do | C1: Mechanik | D1: Elektryk | E1: Mar. Pokł | F1: Artylerz
A2: F-sz 006 | B2: F-sz 006 | C2: F-sz 005 | D2: F-sz 005 | E2: F-sz 002 | F2: F-sz 002
A3: F-sz 007 | B3: F-sz 007 | C3: F-sz 010 | D3: F-sz 010 | E3: F-sz 003 | F3: F-sz 003
A4: F-sz 009 | B4: F-sz 009 | C4: F-sz 013 | D4: F-sz 013 | E4: F-sz 014 | F4: F-sz 014
A5: F-sz 017 | B5: F-sz 017 | C5: F-sz 020 | D5: F-sz 020 | E5: F-sz 018 | F5: F-sz 018
A6: F-sz 023 | B6: F-sz 021 | C6: F-sz 031 | D6: F-sz 031 | E6: F-sz 021 | F6: F-sz 021
A7: F-sz 024 | B7: F-sz 023 | D7: F-sz 004 | E7: F-sz 023 | F7: F-sz 023
A8: F-sz 029 | B8: F-sz 024 | D8: F-sz 019 | E8: F-sz 029 | F8: F-sz 029
B9: F-sz 029 | E9: F-sz 030 | F9: F-sz 030
B10: F-sz 016 | E10: F-sz 016 | F10: F-sz 016

Sheet KAT IV
B1: Dowódca | C1: Bosman | D1: Motorzysta | E1: Mar.pokł
B2: F-sz 001 | C2: F-sz 005 | D2: F-sz 005 | E2: F-sz 001
B3: F-sz 006 | C3: F-sz 010 | D3: F-sz 010 | E3: F-sz 002
B4: F-sz 007 | C4: F-sz 013 | D4: F-sz 013 | E4: F-sz 003
B5: F-sz 009 | C5: F-sz 015 | D5: F-sz 015 | E5: F-sz 005
B6: F-sz 015 | C6: F-sz 020 | D6: F-sz 020 | E6: F-sz 006
B7: F-sz 017 | C7: F-sz 028 | D7: F-sz 028 | E7: F-sz 007
B8: F-sz 022 | C8: F-sz 031 | D8: F-sz 031 | E8: F-sz 013
B9: F-sz 024 | C9: F-sz 004 | D9: F-sz 018 | E9: F-sz 014
B10: F-sz 026 | C10: F-sz 016 | D10: F-sz 019 | E10: F-sz 015
B11: F-sz 002 | E11: F-sz 016
B12: F-sz 004 | E12: F-sz 017
E13: F-sz 018
E14: F-sz 019
E15: F-sz 021
E16: F-sz 023
E17: F-sz 026
E18: F-sz 028
E19: F-sz 031

Sheet STYCZEŃ
A1: SG | B1: ETAT | D1: 44197 | E1: 44197 | F1: 44198 | G1: 44199 | H1: 44200 | I1: 44201 | J1: 44202 | K1: 44203 | L1: 44204 | M1: 44205 | N1: 44206 | O1: 44207 | P1: 44208 | Q1: 44209 | R1: 44210 | S1: 44211 | T1: 44212 | U1: 44213 | V1: 44214 | W1: 44215 | X1: 44216 | Y1: 44217 | Z1: 44218 | AA1: 44219 | AB1: 44220 | AC1: 44221 | AD1: 44222 | AE1: 44223 | AF1: 44224 | AG1: 44225 | AH1: 44226 | AI1: 44227 | AK1: =19*8 -> 152 | AL1: 43922 | AM1: Służba | AN1: Dyżur | AO1: inne | AP1: DT | AQ1: zwolnienia
A2: SG212 | B2: D | C2: BORZĘCKI Tomasz | D2: =#REF! -> #REF! | I2: d | J2: - | L2: d | M2: - | AD2: 4 | AJ2: =_xlfn.CONCAT(#REF!,Tabela13[[#This Row],[FUNKCJONARIUSZ]]) -> #REF! | AK2: =AM2+AN2+AO2-$AK$1+AP2+AQ2 -> -100 | AL2: =MARZEC!AK2 -> #REF! | AM2: =COUNTIF(E2:AI2,"D")*24+COUNTIF(E2:AI2,"12g")*12 -> 48 | AN2: =SUM(COUNTIF(E2:AI2,"k")+COUNTIF(E2:AI2,"s")+COUNTIF(E2:AI2,"wse"))*24+SUM(COUNTIF(E2:AI2,"Pk")+COUNTIF(E2:AI2,"Ps"))*12 -> 0 | AO2: =SUM(E2:AI2)+COUNTIF(E2:AI2,"uw")*8+COUNTIF(E2:AI2,"us")*8+COUNTIF(E2:AI2,"uz")*8 -> 4 | AP2: =COUNTIF(E2:AI2,"DT")*8 -> 0 | AQ2: 0
A3: SG068 | B3: MP | C3: BUKOWSKI Bartosz | D3: =#REF! -> #REF! | O3: 17 | P3: s | Q3: s | R3: s | S3: s | T3: s | U3: s | V3: 12 | W3: - | X3: - | Y3: - | Z3: - | AA3: - | AB3: - | AC3: - | AJ3: =_xlfn.CONCAT(#REF!,Tabela13[[#This Row],[FUNKCJONARIUSZ]]) -> #REF! | AK3: =AM3+AN3+AO3-$AK$1+AP3+AQ3 -> 21 | AL3: =MARZEC!AK3 -> #REF! | AM3: =COUNTIF(E3:AI3,"D")*24+COUNTIF(E3:AI3,"12g")*12 -> 0 | AN3: =SUM(COUNTIF(E3:AI3,"k")+COUNTIF(E3:AI3,"s")+COUNTIF(E3:AI3,"wse"))*24+SUM(COUNTIF(E3:AI3,"Pk")+COUNTIF(E3:AI3,"Ps"))*12 -> 144 | AO3: =SUM(E3:AI3)+COUNTIF(E3:AI3,"uw")*8+COUNTIF(E3:AI3,"us")*8+COUNTIF(E3:AI3,"uz")*8 -> 29 | AP3: =COUNTIF(E3:AI3,"DT")*8 -> 0 | AQ3: 0
A4: SG214 | B4: MP | C4: CHYŁA Katarzyna | D4: =#REF! -> #REF! | E4: s | F4: s | G4: s | H4: ps | I4: - | J4: - | K4: - | L4: - | M4: - | N4: - | O4: - | P4: - | Q4: - | R4: - | W4: d | X4: - | Z4: d | AA4: - | AJ4: =_xlfn.CONCAT(#REF!,Tabela13[[#This Row],[FUNKCJONARIUSZ]]) -> #REF! | AK4: =AM4+AN4+AO4-$AK$1+AP4+AQ4 -> -20 | AL4: =MARZEC!AK4 -> #REF! | AM4: =COUNTIF(E4:AI4,"D")*24+COUNTIF(E4:AI4,"12g")*12 -> 48 | AN4: =SUM(COUNTIF(E4:AI4,"k")+COUNTIF(E4:AI4,"s")+COUNTIF(E4:AI4,"wse"))*24+SUM(COUNTIF(E4:AI4,"Pk")+COUNTIF(E4:AI4,"Ps"))*12 -> 84 | AO4: =SUM(E4:AI4)+COUNTIF(E4:AI4,"uw")*8+COUNTIF(E4:AI4,"us")*8+COUNTIF(E4:AI4,"uz")*8 -> 0 | AP4: =COUNTIF(E4:AI4,"DT")*8 -> 0 | AQ4: 0
A5: SG068 | B5: MP | C5: DRGAS Kamil | D5: =#REF! -> #REF! | G5: d | H5: - | M5: D | N5: - | T5: D | U5: - | X5: d | Y5: - | AA5: D | AB5: - | AE5: 5 | AJ5: =_xlfn.CONCAT(#REF!,Tabela13[[#This Row],[FUNKCJONARIUSZ]]) -> #REF! | AK5: =AM5+AN5+AO5-$AK$1+AP5+AQ5 -> -27 | AL5: =MARZEC!AK5 -> #REF! | AM5: =COUNTIF(E5:AI5,"D")*24+COUNTIF(E5:AI5,"12g")*12 -> 120 | AN5: =SUM(COUNTIF(E5:AI5,"k")+COUNTIF(E5:AI5,"s")+COUNTIF(E5:AI5,"wse"))*24+SUM(COUNTIF(E5:AI5,"Pk")+COUNTIF(E5:AI5,"Ps"))*12 -> 0 | AO5: =SUM(E5:AI5)+COUNTIF(E5:AI5,"uw")*8+COUNTIF(E5:AI5,"us")*8+COUNTIF(E5:AI5,"uz")*8 -> 5 | AP5: =COUNTIF(E5:AI5,"DT")*8 -> 0 | AQ5: 0 | AR5: D | AS5: służba | AT5: 24
A6: SG214 | B6: M | C6: GĄSIEWSKI Dariusz | D6: =#REF! -> #REF! | E6: s | F6: s | G6: s | H6: 10 | I6: - | J6: - | K6: - | L6: - | M6: - | N6: - | O6: - | W6: 6 | X6: 5 | AC6: 16 | AD6: s | AE6: s | AF6: s | AG6: s | AH6: s | AI6: s | AJ6: =_xlfn.CONCAT(#REF!,Tabela13[[#This Row],[FUNKCJONARIUSZ]]) -> #REF! | AK6: =AM6+AN6+AO6-$AK$1+AP6+AQ6 -> 101 | AL6: =MARZEC!AK6 -> #REF! | AM6: =COUNTIF(E6:AI6,"D")*24+COUNTIF(E6:AI6,"12g")*12 -> 0 | AN6: =SUM(COUNTIF(E6:AI6,"k")+COUNTIF(E6:AI6,"s")+COUNTIF(E6:AI6,"wse"))*24+SUM(COUNTIF(E6:AI6,"Pk")+COUNTIF(E6:AI6,"Ps"))*12 -> 216 | AO6: =SUM(E6:AI6)+COUNTIF(E6:AI6,"uw")*8+COUNTIF(E6:AI6,"us")*8+COUNTIF(E6:AI6,"uz")*8 -> 37 | AP6: =COUNTIF(E6:AI6,"DT")*8 -> 0 | AQ6: 0 | AR6: 12g | AS6: służba gazowiec | AT6: 12
A7: SG214 | B7: D | C7: GRZESIAK Sebastian | D7: =#REF! -> #REF! | O7: 10 | P7: s | Q7: s | R7: s | S7: s | T7: s | U7: s | V7: 11 | W7: - | X7: - | Y7: 8 | Z7: 8 | AA7: - | AB7: - | AC7: - | AJ7: =_xlfn.CONCAT(#REF!,Tabela13[[#This Row],[FUNKCJONARIUSZ]]) -> #REF! | AK7: =AM7+AN7+AO7-$AK$1+AP7+AQ7 -> 29 | AL7: =MARZEC!AK7 -> #REF! | AM7: =COUNTIF(E7:AI7,"D")*24+COUNTIF(E7:AI7,"12g")*12 -> 0 | AN7: =SUM(COUNTIF(E7:AI7,"k")+COUNTIF(E7:AI7,"s")+COUNTIF(E7:AI7,"wse"))*24+SUM(COUNTIF(E7:AI7,"Pk")+COUNTIF(E7:AI7,"Ps"))*12 -> 144 | AO7: =SUM(E7:AI7)+COUNTIF(E7:AI7,"uw")*8+COUNTIF(E7:AI7,"us")*8+COUNTIF(E7:AI7,"uz")*8 -> 37 | AP7: =COUNTIF(E7:AI7,"DT")*8 -> 0 | AQ7: 0 | AR7: ps | AS7: 1/2 dyżuru | AT7: 12
A8: SG214 | B8: D | C8: JAKIMIAK Marcin | D8: =#REF! -> #REF! | H8: 16 | I8: s | J8: s | K8: s | L8: s | M8: s | N8: s | O8: 15 | P8: - | Q8: - | R8: - | S8: - | T8: - | U8: - | V8: - | AD8: 5 | AJ8: =_xlfn.CONCAT(#REF!,Tabela13[[#This Row],[FUNKCJONARIUSZ]]) -> #REF! | AK8: =AM8+AN8+AO8-$AK$1+AP8+AQ8 -> 28 | AL8: =MARZEC!AK8 -> #REF! | AM8: =COUNTIF(E8:AI8,"D")*24+COUNTIF(E8:AI8,"12g")*12 -> 0 | AN8: =SUM(COUNTIF(E8:AI8,"k")+COUNTIF(E8:AI8,"s")+COUNTIF(E8:AI8,"wse"))*24+SUM(COUNTIF(E8:AI8,"Pk")+COUNTIF(E8:AI8,"Ps"))*12 -> 144 | AO8: =SUM(E8:AI8)+COUNTIF(E8:AI8,"uw")*8+COUNTIF(E8:AI8,"us")*8+COUNTIF(E8:AI8,"uz")*8 -> 36 | AP8: =COUNTIF(E8:AI8,"DT")*8 -> 0 | AQ8: 0 | AR8: s | AS8: dyżur Ś-cie | AT8: 24
A9: SG214 | B9: D | C9: KALITA Mariusz | D9: =#REF! -> #REF! | E9: - | F9: - | G9: - | H9: - | O9: us | P9: us | Q9: us | R9: us | S9: us | W9: 5 | AC9: 17 | AD9: s | AE9: s | AF9: s | AG9: s | AH9: s | AI9: s | AJ9: =_xlfn.CONCAT(#REF!,Tabela13[[#This Row],[FUNKCJONARIUSZ]]) -> #REF! | AK9: =AM9+AN9+AO9-$AK$1+AP9+AQ9 -> 54 | AL9: =MARZEC!AK9 -> #REF! | AM9: =COUNTIF(E9:AI9,"D")*24+COUNTIF(E9:AI9,"12g")*12 -> 0 | AN9: =SUM(COUNTIF(E9:AI9,"k")+COUNTIF(E9:AI9,"s")+COUNTIF(E9:AI9,"wse"))*24+SUM(COUNTIF(E9:AI9,"Pk")+COUNTIF(E9:AI9,"Ps"))*12 -> 144 | AO9: =SUM(E9:AI9)+COUNTIF(E9:AI9,"uw")*8+COUNTIF(E9:AI9,"us")*8+COUNTIF(E9:AI9,"uz")*8 -> 62 | AP9: =COUNTIF(E9:AI9,"DT")*8 -> 0 | AQ9: 0 | AR9: us | AS9: urlop staż | AT9: 8
A10: SG212 | B10: M | C10: ŁUKACZ Sławomir | D10: =#REF! -> #REF! | H10: us | I10: us | J10: - | K10: us | L10: us | M10: - | N10: - | O10: us | P10: us | Q10: us | R10: us | S10: us | V10: 17 | W10: s | X10: s | Y10: s | Z10: s | AA10: s | AB10: s | AC10: 11 | AD10: - | AE10: - | AF10: - | AG10: - | AH10: - | AI10: - | AJ10: =_xlfn.CONCAT(#REF!,Tabela13[[#This Row],[FUNKCJONARIUSZ]]) -> #REF! | AK10: =AM10+AN10+AO10-$AK$1+AP10+AQ10 -> 92 | AL10: =MARZEC!AK10 -> #REF! | AM10: =COUNTIF(E10:AI10,"D")*24+COUNTIF(E10:AI10,"12g")*12 -> 0 | AN10: =SUM(COUNTIF(E10:AI10,"k")+COUNTIF(E10:AI10,"s")+COUNTIF(E10:AI10,"wse"))*24+SUM(COUNTIF(E10:AI10,"Pk")+COUNTIF(E10:AI10,"Ps"))*12 -> 144 | AO10: =SUM(E10:AI10)+COUNTIF(E10:AI10,"uw")*8+COUNTIF(E10:AI10,"us")*8+COUNTIF(E10:AI10,"uz")*8 -> 100 | AP10: =COUNTIF(E10:AI10,"DT")*8 -> 0 | AQ10: 0 | AR10: uw | AS10: urlop wypoczynkowy | AT10: 8
A11: SG212 | B11: M | C11: MIZGIER Bartosz | D11: =#REF! -> #REF! | E11: - | F11: - | G11: - | H11: - | U11: D | V11: - | Y11: 4.5 | AD11: d | AE11: - | AJ11: =_xlfn.CONCAT(#REF!,Tabela13[[#This Row],[FUNKCJONARIUSZ]]) -> #REF! | AK11: =AM11+AN11+AO11-$AK$1+AP11+AQ11 -> -99.5 | AL11: =MARZEC!AK11 -> #REF! | AM11: =COUNTIF(E11:AI11,"D")*24+COUNTIF(E11:AI11,"12g")*12 -> 48 | AN11: =SUM(COUNTIF(E11:AI11,"k")+COUNTIF(E11:AI11,"s")+COUNTIF(E11:AI11,"wse"))*24+SUM(COUNTIF(E11:AI11,"Pk")+COUNTIF(E11:AI11,"Ps"))*12 -> 0 | AO11: =SUM(E11:AI11)+COUNTIF(E11:AI11,"uw")*8+COUNTIF(E11:AI11,"us")*8+COUNTIF(E11:AI11,"uz")*8 -> 4.5 | AP11: =COUNTIF(E11:AI11,"DT")*8 -> 0 | AQ11: 0 | AR11: uz | AS11: urlop zaległy | AT11: 8
A12: SG070 | B12: MP | C12: MŁYŃSKI Błażej | D12: =#REF! -> #REF! | E12: - | F12: - | G12: - | H12: - | P12: d | Q12: - | S12: d | T12: - | AJ12: =_xlfn.CONCAT(#REF!,Tabela13[[#This Row],[FUNKCJONARIUSZ]]) -> #REF! | AK12: =AM12+AN12+AO12-$AK$1+AP12+AQ12 -> -104 | AL12: =MARZEC!AK12 -> #REF! | AM12: =COUNTIF(E12:AI12,"D")*24+COUNTIF(E12:AI12,"12g")*12 -> 48 | AN12: =SUM(COUNTIF(E12:AI12,"k")+COUNTIF(E12:AI12,"s")+COUNTIF(E12:AI12,"wse"))*24+SUM(COUNTIF(E12:AI12,"Pk")+COUNTIF(E12:AI12,"Ps"))*12 -> 0 | AO12: =SUM(E12:AI12)+COUNTIF(E12:AI12,"uw")*8+COUNTIF(E12:AI12,"us")*8+COUNTIF(E12:AI12,"uz")*8 -> 0 | AP12: =COUNTIF(E12:AI12,"DT")*8 -> 0 | AQ12: 0 | AR12: pk | AS12: 1/2 dyżuru | AT12: 12
A13: SG212 | B13: ZD | C13: MOSKALONEK Hubert | D13: =#REF! -> #REF! | L13: - | M13: - | N13: - | V13: 17 | W13: s | X13: s | Y13: s | Z13: s | AA13: s | AB13: s | AC13: 11 | AD13: - | AE13: - | AF13: - | AG13: - | AH13: - | AI13: - | AJ13: =_xlfn.CONCAT(#REF!,Tabela13[[#This Row],[FUNKCJONARIUSZ]]) -> #REF! | AK13: =AM13+AN13+AO13-$AK$1+AP13+AQ13 -> 20 | AL13: =MARZEC!AK13 -> #REF! | AM13: =COUNTIF(E13:AI13,"D")*24+COUNTIF(E13:AI13,"12g")*12 -> 0 | AN13: =SUM(COUNTIF(E13:AI13,"k")+COUNTIF(E13:AI13,"s")+COUNTIF(E13:AI13,"wse"))*24+SUM(COUNTIF(E13:AI13,"Pk")+COUNTIF(E13:AI13,"Ps"))*12 -> 144 | AO13: =SUM(E13:AI13)+COUNTIF(E13:AI13,"uw")*8+COUNTIF(E13:AI13,"us")*8+COUNTIF(E13:AI13,"uz")*8 -> 28 | AP13: =COUNTIF(E13:AI13,"DT")*8 -> 0 | AQ13: 0 | AR13: k | AS13: dyżur K-g | AT13: 24
A14: SG070 | B14: D | C14: NOWICKI Radosław | D14: =#REF! -> #REF! | H14: uz | J14: D | K14: - | Z14: 12g | AD14: 5 | AE14: d | AH14: d | AJ14: =_xlfn.CONCAT(#REF!,Tabela13[[#This Row],[FUNKCJONARIUSZ]]) -> #REF! | AK14: =AM14+AN14+AO14-$AK$1+AP14+AQ14 -> -55 | AL14: =MARZEC!AK14 -> #REF! | AM14: =COUNTIF(E14:AI14,"D")*24+COUNTIF(E14:AI14,"12g")*12 -> 84 | AN14: =SUM(COUNTIF(E14:AI14,"k")+COUNTIF(E14:AI14,"s")+COUNTIF(E14:AI14,"wse"))*24+SUM(COUNTIF(E14:AI14,"Pk")+COUNTIF(E14:AI14,"Ps"))*12 -> 0 | AO14: =SUM(E14:AI14)+COUNTIF(E14:AI14,"uw")*8+COUNTIF(E14:AI14,"us")*8+COUNTIF(E14:AI14,"uz")*8 -> 13 | AP14: =COUNTIF(E14:AI14,"DT")*8 -> 0 | AQ14: 0 | AR14: wse | AS14: WSE | AT14: 24
A15: SG212 | B15: ZD | C15: PALUCH Łukasz | D15: =#REF! -> #REF! | W15: L4 | X15: L4 | Y15: L4 | Z15: L4 | AA15: - | AB15: - | AC15: L4 | AD15: L4 | AE15: L4 | AF15: L4 | AG15: L4 | AH15: - | AI15: - | AJ15: =_xlfn.CONCAT(#REF!,Tabela13[[#This Row],[FUNKCJONARIUSZ]]) -> #REF! | AK15: =AM15+AN15+AO15-$AK$1+AP15+AQ15 -> -104 | AL15: =MARZEC!AK15 -> -95 | AM15: =COUNTIF(E15:AI15,"D")*24+COUNTIF(E15:AI15,"12g")*12 -> 0 | AN15: =SUM(COUNTIF(E15:AI15,"k")+COUNTIF(E15:AI15,"s")+COUNTIF(E15:AI15,"wse"))*24+SUM(COUNTIF(E15:AI15,"Pk")+COUNTIF(E15:AI15,"Ps"))*12 -> 0 | AO15: =SUM(E15:AI15)+COUNTIF(E15:AI15,"uw")*8+COUNTIF(E15:AI15,"us")*8+COUNTIF(E15:AI15,"uz")*8 -> 0 | AP15: =COUNTIF(E15:AI15,"DT")*8 -> 0 | AQ15: =2*24 -> 48 | AR15: l4 | AS15: Zwolnienia lekarskie | AT15: ?
A16: SG070 | B16: MP | C16: PRYCA Adam | D16: =#REF! -> #REF! | AC16: 17 | AD16: s | AE16: s | AF16: s | AG16: s | AH16: s | AI16: s | AJ16: =_xlfn.CONCAT(#REF!,Tabela13[[#This Row],[FUNKCJONARIUSZ]]) -> #REF! | AK16: =AM16+AN16+AO16-$AK$1+AP16+AQ16 -> 9 | AL16: =MARZEC!AK16 -> #REF! | AM16: =COUNTIF(E16:AI16,"D")*24+COUNTIF(E16:AI16,"12g")*12 -> 0 | AN16: =SUM(COUNTIF(E16:AI16,"k")+COUNTIF(E16:AI16,"s")+COUNTIF(E16:AI16,"wse"))*24+SUM(COUNTIF(E16:AI16,"Pk")+COUNTIF(E16:AI16,"Ps"))*12 -> 144 | AO16: =SUM(E16:AI16)+COUNTIF(E16:AI16,"uw")*8+COUNTIF(E16:AI16,"us")*8+COUNTIF(E16:AI16,"uz")*8 -> 17 | AP16: =COUNTIF(E16:AI16,"DT")*8 -> 0 | AQ16: 0
A17: SG212 | B17: MP | C17: ROZMYTAŃSKA - PEŁECH Olga | D17: =#REF! -> #REF! | E17: D | F17: - | O17: - | P17: - | V17: 17 | W17: s | X17: s | Y17: s | Z17: s | AA17: s | AB17: s | AC17: 11 | AD17: - | AE17: - | AF17: - | AG17: - | AH17: - | AI17: - | AJ17: =_xlfn.CONCAT(#REF!,Tabela13[[#This Row],[FUNKCJONARIUSZ]]) -> #REF! | AK17: =AM17+AN17+AO17-$AK$1+AP17+AQ17 -> 44 | AL17: =MARZEC!AK17 -> #REF! | AM17: =COUNTIF(E17:AI17,"D")*24+COUNTIF(E17:AI17,"12g")*12 -> 24 | AN17: =SUM(COUNTIF(E17:AI17,"k")+COUNTIF(E17:AI17,"s")+COUNTIF(E17:AI17,"wse"))*24+SUM(COUNTIF(E17:AI17,"Pk")+COUNTIF(E17:AI17,"Ps"))*12 -> 144 | AO17: =SUM(E17:AI17)+COUNTIF(E17:AI17,"uw")*8+COUNTIF(E17:AI17,"us")*8+COUNTIF(E17:AI17,"uz")*8 -> 28 | AP17: =COUNTIF(E17:AI17,"DT")*8 -> 0 | AQ17: 0
A18: SG007 | B18: MP | C18: SAJDAK Patryk | D18: =#REF! -> #REF! | F18: D | G18: - | K18: 12g | V18: d | X18: 5 | AF18: d | AI18: 16 | AJ18: =_xlfn.CONCAT(#REF!,Tabela13[[#This Row],[FUNKCJONARIUSZ]]) -> #REF! | AK18: =AM18+AN18+AO18-$AK$1+AP18+AQ18 -> -47 | AL18: =MARZEC!AK18 -> #REF! | AM18: =COUNTIF(E18:AI18,"D")*24+COUNTIF(E18:AI18,"12g")*12 -> 84 | AN18: =SUM(COUNTIF(E18:AI18,"k")+COUNTIF(E18:AI18,"s")+COUNTIF(E18:AI18,"wse"))*24+SUM(COUNTIF(E18:AI18,"Pk")+COUNTIF(E18:AI18,"Ps"))*12 -> 0 | AO18: =SUM(E18:AI18)+COUNTIF(E18:AI18,"uw")*8+COUNTIF(E18:AI18,"us")*8+COUNTIF(E18:AI18,"uz")*8 -> 21 | AP18: =COUNTIF(E18:AI18,"DT")*8 -> 0 | AQ18: 0
A19: SG214 | B19: M | C19: SPRUTTA Radosław | D19: =#REF! -> #REF! | H19: 16 | I19: s | J19: s | K19: s | L19: s | M19: s | N19: s | O19: 11 | P19: - | Q19: - | R19: - | S19: - | T19: - | U19: - | W19: 6 | X19: 5 | Y19: 14 | Z19: 14 | AC19: 3 | AJ19: =_xlfn.CONCAT(#REF!,Tabela13[[#This Row],[FUNKCJONARIUSZ]]) -> #REF! | AK19: =AM19+AN19+AO19-$AK$1+AP19+AQ19 -> 61 | AL19: =MARZEC!AK19 -> #REF! | AM19: =COUNTIF(E19:AI19,"D")*24+COUNTIF(E19:AI19,"12g")*12 -> 0 | AN19: =SUM(COUNTIF(E19:AI19,"k")+COUNTIF(E19:AI19,"s")+COUNTIF(E19:AI19,"wse"))*24+SUM(COUNTIF(E19:AI19,"Pk")+COUNTIF(E19:AI19,"Ps"))*12 -> 144 | AO19: =SUM(E19:AI19)+COUNTIF(E19:AI19,"uw")*8+COUNTIF(E19:AI19,"us")*8+COUNTIF(E19:AI19,"uz")*8 -> 69 | AP19: =COUNTIF(E19:AI19,"DT")*8 -> 0 | AQ19: 0
A20: SG070 | B20: D | C20: STRANC Andrzej | D20: =#REF! -> #REF! | O20: 17 | P20: s | Q20: s | R20: s | S20: s | T20: s | U20: s | V20: 11 | W20: uw | X20: uw | Y20: uw | Z20: uw | AA20: - | AB20: - | AC20: uw | AD20: uw | AE20: uw | AF20: uw | AG20: uw | AH20: - | AI20: - | AJ20: =_xlfn.CONCAT(#REF!,Tabela13[[#This Row],[FUNKCJONARIUSZ]]) -> #REF! | AK20: =AM20+AN20+AO20-$AK$1+AP20+AQ20 -> 92 | AL20: =MARZEC!AK20 -> #REF! | AM20: =COUNTIF(E20:AI20,"D")*24+COUNTIF(E20:AI20,"12g")*12 -> 0 | AN20: =SUM(COUNTIF(E20:AI20,"k")+COUNTIF(E20:AI20,"s")+COUNTIF(E20:AI20,"wse"))*24+SUM(COUNTIF(E20:AI20,"Pk")+COUNTIF(E20:AI20,"Ps"))*12 -> 144 | AO20: =SUM(E20:AI20)+COUNTIF(E20:AI20,"uw")*8+COUNTIF(E20:AI20,"us")*8+COUNTIF(E20:AI20,"uz")*8 -> 100 | AP20: =COUNTIF(E20:AI20,"DT")*8 -> 0 | AQ20: 0
A21: SG212 | B21: D | C21: SZCZEPANIAK Zbigniew | D21: =#REF! -> #REF! | V21: 17 | W21: s | X21: s | Y21: s | Z21: s | AA21: s | AB21: s | AC21: 11 | AD21: - | AE21: - | AF21: - | AG21: - | AH21: - | AI21: - | AJ21: =_xlfn.CONCAT(#REF!,Tabela13[[#This Row],[FUNKCJONARIUSZ]]) -> #REF! | AK21: =AM21+AN21+AO21-$AK$1+AP21+AQ21 -> 20 | AL21: =MARZEC!AK21 -> #REF! | AM21: =COUNTIF(E21:AI21,"D")*24+COUNTIF(E21:AI21,"12g")*12 -> 0 | AN21: =SUM(COUNTIF(E21:AI21,"k")+COUNTIF(E21:AI21,"s")+COUNTIF(E21:AI21,"wse"))*24+SUM(COUNTIF(E21:AI21,"Pk")+COUNTIF(E21:AI21,"Ps"))*12 -> 144 | AO21: =SUM(E21:AI21)+COUNTIF(E21:AI21,"uw")*8+COUNTIF(E21:AI21,"us")*8+COUNTIF(E21:AI21,"uz")*8 -> 28 | AP21: =COUNTIF(E21:AI21,"DT")*8 -> 0 | AQ21: 0
A22: SG068 | B22: D | C22: SZNAJDER Wiktor | D22: =#REF! -> #REF! | H22: uz | I22: uz | K22: 6 | O22: D | P22: - | Y22: d | Z22: - | AC22: - | AJ22: =_xlfn.CONCAT(#REF!,Tabela13[[#This Row],[FUNKCJONARIUSZ]]) -> #REF! | AK22: =AM22+AN22+AO22-$AK$1+AP22+AQ22 -> -82 | AL22: =MARZEC!AK22 -> #REF! | AM22: =COUNTIF(E22:AI22,"D")*24+COUNTIF(E22:AI22,"12g")*12 -> 48 | AN22: =SUM(COUNTIF(E22:AI22,"k")+COUNTIF(E22:AI22,"s")+COUNTIF(E22:AI22,"wse"))*24+SUM(COUNTIF(E22:AI22,"Pk")+COUNTIF(E22:AI22,"Ps"))*12 -> 0 | AO22: =SUM(E22:AI22)+COUNTIF(E22:AI22,"uw")*8+COUNTIF(E22:AI22,"us")*8+COUNTIF(E22:AI22,"uz")*8 -> 22 | AP22: =COUNTIF(E22:AI22,"DT")*8 -> 0 | AQ22: 0
A23: SG214 | B23: ZD | C23: SZYMAŃSKI Tomasz Paweł | D23: =#REF! -> #REF! | E23: s | F23: s | G23: s | H23: 13 | I23: - | J23: - | K23: - | L23: - | M23: - | N23: - | O23: - | V23: uz | W23: uz | X23: uz | Y23: uz | Z23: uz | AA23: - | AB23: - | AC23: uz | AD23: uz | AE23: uz | AF23: uz | AJ23: =_xlfn.CONCAT(#REF!,Tabela13[[#This Row],[FUNKCJONARIUSZ]]) -> #REF! | AK23: =AM23+AN23+AO23-$AK$1+AP23+AQ23 -> 5 | AL23: =MARZEC!AK23 -> #REF! | AM23: =COUNTIF(E23:AI23,"D")*24+COUNTIF(E23:AI23,"12g")*12 -> 0 | AN23: =SUM(COUNTIF(E23:AI23,"k")+COUNTIF(E23:AI23,"s")+COUNTIF(E23:AI23,"wse"))*24+SUM(COUNTIF(E23:AI23,"Pk")+COUNTIF(E23:AI23,"Ps"))*12 -> 72 | AO23: =SUM(E23:AI23)+COUNTIF(E23:AI23,"uw")*8+COUNTIF(E23:AI23,"us")*8+COUNTIF(E23:AI23,"uz")*8 -> 85 | AP23: =COUNTIF(E23:AI23,"DT")*8 -> 0 | AQ23: 0
A24: SG212 | B24: D | C24: ŚWIREPO Piotr | D24: =#REF! -> #REF! | N24: d | O24: 1 | AC24: us | AD24: us | AE24: us | AF24: us | AG24: us | AJ24: =_xlfn.CONCAT(#REF!,Tabela13[[#This Row],[FUNKCJONARIUSZ]]) -> #REF! | AK24: =AM24+AN24+AO24-$AK$1+AP24+AQ24 -> -87 | AL24: =MARZEC!AK24 -> #REF! | AM24: =COUNTIF(E24:AI24,"D")*24+COUNTIF(E24:AI24,"12g")*12 -> 24 | AN24: =SUM(COUNTIF(E24:AI24,"k")+COUNTIF(E24:AI24,"s")+COUNTIF(E24:AI24,"wse"))*24+SUM(COUNTIF(E24:AI24,"Pk")+COUNTIF(E24:AI24,"Ps"))*12 -> 0 | AO24: =SUM(E24:AI24)+COUNTIF(E24:AI24,"uw")*8+COUNTIF(E24:AI24,"us")*8+COUNTIF(E24:AI24,"uz")*8 -> 41 | AP24: =COUNTIF(E24:AI24,"DT")*8 -> 0 | AQ24: 0
A25: SG068 | B25: MP | C25: WALCZAK Oskar | D25: =#REF! -> #REF! | E25: - | F25: - | G25: - | H25: - | I25: - | J25: - | K25: - | L25: - | M25: - | N25: - | O25: - | P25: - | Q25: - | R25: - | S25: - | T25: - | U25: - | V25: - | W25: - | X25: - | Y25: - | Z25: - | AA25: - | AB25: - | AC25: - | AD25: - | AE25: - | AF25: - | AG25: - | AH25: - | AI25: - | AJ25: =_xlfn.CONCAT(#REF!,Tabela13[[#This Row],[FUNKCJONARIUSZ]]) -> #REF! | AK25: =AM25+AN25+AO25-$AK$1+AP25+AQ25 -> -152 | AL25: =MARZEC!AK25 -> #REF! | AM25: =COUNTIF(E25:AI25,"D")*24+COUNTIF(E25:AI25,"12g")*12 -> 0 | AN25: =SUM(COUNTIF(E25:AI25,"k")+COUNTIF(E25:AI25,"s")+COUNTIF(E25:AI25,"wse"))*24+SUM(COUNTIF(E25:AI25,"Pk")+COUNTIF(E25:AI25,"Ps"))*12 -> 0 | AO25: =SUM(E25:AI25)+COUNTIF(E25:AI25,"uw")*8+COUNTIF(E25:AI25,"us")*8+COUNTIF(E25:AI25,"uz")*8 -> 0 | AP25: =COUNTIF(E25:AI25,"DT")*8 -> 0 | AQ25: 0
A26: SG214 | B26: ZD | C26: WALKOWIAK Wojciech | D26: =#REF! -> #REF! | E26: - | F26: - | G26: - | H26: - | L26: 12g | Q26: d | R26: - | AC26: 17 | AD26: s | AE26: s | AF26: s | AG26: s | AH26: s | AI26: s | AJ26: =_xlfn.CONCAT(#REF!,Tabela13[[#This Row],[FUNKCJONARIUSZ]]) -> #REF! | AK26: =AM26+AN26+AO26-$AK$1+AP26+AQ26 -> 45 | AL26: =MARZEC!AK26 -> #REF! | AM26: =COUNTIF(E26:AI26,"D")*24+COUNTIF(E26:AI26,"12g")*12 -> 36 | AN26: =SUM(COUNTIF(E26:AI26,"k")+COUNTIF(E26:AI26,"s")+COUNTIF(E26:AI26,"wse"))*24+SUM(COUNTIF(E26:AI26,"Pk")+COUNTIF(E26:AI26,"Ps"))*12 -> 144 | AO26: =SUM(E26:AI26)+COUNTIF(E26:AI26,"uw")*8+COUNTIF(E26:AI26,"us")*8+COUNTIF(E26:AI26,"uz")*8 -> 17 | AP26: =COUNTIF(E26:AI26,"DT")*8 -> 0 | AQ26: 0
A27: SG068 | B27: D | C27: WERSZNER Piotr | D27: =#REF! -> #REF! | E27: 8 | H27: d | I27: - | K27: d | L27: - | O27: - | Q27: 8 | R27: d | S27: - | T27: - | U27: - | V27: - | W27: - | X27: 4 | Y27: 12g | AC27: d | AD27: - | AG27: d | AH27: - | AJ27: =_xlfn.CONCAT(#REF!,Tabela13[[#This Row],[FUNKCJONARIUSZ]]) -> #REF! | AK27: =AM27+AN27+AO27-$AK$1+AP27+AQ27 -> 0 | AL27: =MARZEC!AK27 -> #REF! | AM27: =COUNTIF(E27:AI27,"D")*24+COUNTIF(E27:AI27,"12g")*12 -> 132 | AN27: =SUM(COUNTIF(E27:AI27,"k")+COUNTIF(E27:AI27,"s")+COUNTIF(E27:AI27,"wse"))*24+SUM(COUNTIF(E27:AI27,"Pk")+COUNTIF(E27:AI27,"Ps"))*12 -> 0 | AO27: =SUM(E27:AI27)+COUNTIF(E27:AI27,"uw")*8+COUNTIF(E27:AI27,"us")*8+COUNTIF(E27:AI27,"uz")*8 -> 20 | AP27: =COUNTIF(E27:AI27,"DT")*8 -> 0 | AQ27: 0
A28: SG212 | B28: D | C28: WILCZEK Krzysztof | D28: =#REF! -> #REF! | E28: s | F28: s | G28: s | H28: ps | I28: us | J28: - | K28: us | L28: us | M28: - | N28: - | O28: us | AJ28: =_xlfn.CONCAT(#REF!,Tabela13[[#This Row],[FUNKCJONARIUSZ]]) -> #REF! | AK28: =AM28+AN28+AO28-$AK$1+AP28+AQ28 -> -36 | AL28: =MARZEC!AK28 -> #REF! | AM28: =COUNTIF(E28:AI28,"D")*24+COUNTIF(E28:AI28,"12g")*12 -> 0 | AN28: =SUM(COUNTIF(E28:AI28,"k")+COUNTIF(E28:AI28,"s")+COUNTIF(E28:AI28,"wse"))*24+SUM(COUNTIF(E28:AI28,"Pk")+COUNTIF(E28:AI28,"Ps"))*12 -> 84 | AO28: =SUM(E28:AI28)+COUNTIF(E28:AI28,"uw")*8+COUNTIF(E28:AI28,"us")*8+COUNTIF(E28:AI28,"uz")*8 -> 32 | AP28: =COUNTIF(E28:AI28,"DT")*8 -> 0 | AQ28: 0
A29: SG068 | B29: M | C29: WITWICKI Adrian | D29: =#REF! -> #REF! | O29: 17 | P29: s | Q29: s | R29: s | S29: s | T29: s | U29: s | V29: 11 | W29: - | X29: - | Y29: - | Z29: - | AA29: - | AB29: - | AC29: - | AJ29: =_xlfn.CONCAT(#REF!,Tabela13[[#This Row],[FUNKCJONARIUSZ]]) -> #REF! | AK29: =AM29+AN29+AO29-$AK$1+AP29+AQ29 -> 20 | AL29: =MARZEC!AK29 -> #REF! | AM29: =COUNTIF(E29:AI29,"D")*24+COUNTIF(E29:AI29,"12g")*12 -> 0 | AN29: =SUM(COUNTIF(E29:AI29,"k")+COUNTIF(E29:AI29,"s")+COUNTIF(E29:AI29,"wse"))*24+SUM(COUNTIF(E29:AI29,"Pk")+COUNTIF(E29:AI29,"Ps"))*12 -> 144 | AO29: =SUM(E29:AI29)+COUNTIF(E29:AI29,"uw")*8+COUNTIF(E29:AI29,"us")*8+COUNTIF(E29:AI29,"uz")*8 -> 28 | AP29: =COUNTIF(E29:AI29,"DT")*8 -> 0 | AQ29: 0
A30: SG212 | B30: ZD | C30: ZAJĄC Rafał | D30: =#REF! -> #REF! | H30: 17 | I30: s | J30: s | K30: s | L30: s | M30: s | N30: s | O30: 10 | P30: - | Q30: - | R30: - | S30: - | T30: - | U30: - | V30: - | AB30: d | AD30: 5 | AJ30: =_xlfn.CONCAT(#REF!,Tabela13[[#This Row],[FUNKCJONARIUSZ]]) -> #REF! | AK30: =AM30+AN30+AO30-$AK$1+AP30+AQ30 -> 48 | AL30: =MARZEC!AK30 -> #REF! | AM30: =COUNTIF(E30:AI30,"D")*24+COUNTIF(E30:AI30,"12g")*12 -> 24 | AN30: =SUM(COUNTIF(E30:AI30,"k")+COUNTIF(E30:AI30,"s")+COUNTIF(E30:AI30,"wse"))*24+SUM(COUNTIF(E30:AI30,"Pk")+COUNTIF(E30:AI30,"Ps"))*12 -> 144 | AO30: =SUM(E30:AI30)+COUNTIF(E30:AI30,"uw")*8+COUNTIF(E30:AI30,"us")*8+COUNTIF(E30:AI30,"uz")*8 -> 32 | AP30: =COUNTIF(E30:AI30,"DT")*8 -> 0 | AQ30: 0
A31: SG007 | B31: D | C31: ZATWARNICKA Joanna | D31: =#REF! -> #REF! | H31: 16 | I31: s | J31: s | K31: s | L31: s | M31: s | N31: s | O31: 11 | P31: - | Q31: - | R31: - | S31: - | T31: - | U31: - | V31: - | AJ31: =_xlfn.CONCAT(#REF!,Tabela13[[#This Row],[FUNKCJONARIUSZ]]) -> #REF! | AK31: =AM31+AN31+AO31-$AK$1+AP31+AQ31 -> 19 | AL31: =MARZEC!AK31 -> #REF! | AM31: =COUNTIF(E31:AI31,"D")*24+COUNTIF(E31:AI31,"12g")*12 -> 0 | AN31: =SUM(COUNTIF(E31:AI31,"k")+COUNTIF(E31:AI31,"s")+COUNTIF(E31:AI31,"wse"))*24+SUM(COUNTIF(E31:AI31,"Pk")+COUNTIF(E31:AI31,"Ps"))*12 -> 144 | AO31: =SUM(E31:AI31)+COUNTIF(E31:AI31,"uw")*8+COUNTIF(E31:AI31,"us")*8+COUNTIF(E31:AI31,"uz")*8 -> 27 | AP31: =COUNTIF(E31:AI31,"DT")*8 -> 0 | AQ31: 0
A32: SG212 | B32: M | C32: ZEMBRZUSKI Krzysztof | D32: =#REF! -> #REF! | H32: uz | I32: uz | J32: - | K32: uz | L32: uz | M32: - | N32: - | O32: uz | P32: uz | Q32: uz | R32: uz | S32: uz | T32: - | U32: - | V32: uz | W32: uz | X32: uz | Y32: uz | Z32: uz | AA32: - | AB32: - | AC32: uz | AD32: uz | AE32: uz | AF32: uz | AG32: uz | AH32: - | AI32: - | AJ32: =_xlfn.CONCAT(#REF!,Tabela13[[#This Row],[FUNKCJONARIUSZ]]) -> #REF! | AK32: =AM32+AN32+AO32-$AK$1+AP32+AQ32 -> 0 | AL32: =MARZEC!AK32 -> #REF! | AM32: =COUNTIF(E32:AI32,"D")*24+COUNTIF(E32:AI32,"12g")*12 -> 0 | AN32: =SUM(COUNTIF(E32:AI32,"k")+COUNTIF(E32:AI32,"s")+COUNTIF(E32:AI32,"wse"))*24+SUM(COUNTIF(E32:AI32,"Pk")+COUNTIF(E32:AI32,"Ps"))*12 -> 0 | AO32: =SUM(E32:AI32)+COUNTIF(E32:AI32,"uw")*8+COUNTIF(E32:AI32,"us")*8+COUNTIF(E32:AI32,"uz")*8 -> 152 | AP32: =COUNTIF(E32:AI32,"DT")*8 -> 0 | AQ32: 0
C33: SŁUŻBA | E33: =COUNTIF(E2:E32,"D") -> 1 | F33: =COUNTIF(F2:F32,"D") -> 1 | G33: =COUNTIF(G2:G32,"D") -> 1 | H33: =COUNTIF(H2:H32,"D") -> 1 | I33: =COUNTIF(I2:I32,"D") -> 1 | J33: =COUNTIF(J2:J32,"D") -> 1 | K33: =COUNTIF(K2:K32,"D") -> 1 | L33: =COUNTIF(L2:L32,"D") -> 1 | ... AI33: =COUNTIF(AI2:AI32,"D") -> 0
C34: SUMA
C35: SUMA
W36: SZCZEPANIAK | AD36: KALITA | AH36: KALITA
W37: MOSKALONEK | AD37: WALKOWIAK | AH37: WALKOWIAK
W38: ŁUKACZ | AD38: GĄSIEWSKI | AH38: GĄSIEWSKI
W39: ROZMYTAŃSKA | AD39: PRYCA | AH39: PRYCA
A41: SG | B41: ETAT | E41: 44197 | F41: 44198 | G41: 44199 | H41: 44200 | I41: 44201 | J41: 44202 | K41: 44203 | L41: 44204 | M41: 44205 | N41: 44206 | O41: 44207 | P41: 44208 | Q41: 44209 | R41: 44210 | S41: 44211 | T41: 44212 | U41: 44213 | V41: 44214 | W41: 44215 | X41: 44216 | Y41: 44217 | Z41: 44218 | AA41: 44219 | AB41: 44220 | AC41: 44221 | AD41: 44222 | AE41: 44223 | AF41: 44224 | AG41: 44225 | AH41: 44226 | AI41: 44227 | AK41: =19*8 -> 152 | AL41: 43922 | AM41: Służba | AN41: Dyżur | AO41: inne | AP41: DT | AQ41: zwolnienia
...

Sheet służby druk
B1: styczeń 2021 r.
A2: Dyżurny Wachty Portowej
A3: 44197 | C3: DYŻURNY | D3: wachtowy | E3: wachtowy
A4: 1 | B4: pt. | C4: =VLOOKUP("D",STYCZEŃ!$E$2:$AJ$32,32,0) -> #REF!
A5: 2 | B5: sob. | C5: =VLOOKUP("D",STYCZEŃ!F$2:$AJ$32,31,0) -> #REF!
A6: 3 | B6: niedz. | C6: =VLOOKUP("D",STYCZEŃ!G$2:$AJ$32,30,0) -> #REF!
A7: 4 | B7: pon. | C7: =VLOOKUP("D",STYCZEŃ!H$2:$AJ$32,29,0) -> #REF!
A8: 5 | B8: wt. | C8: =VLOOKUP("D",STYCZEŃ!I$2:$AJ$32,28,0) -> #REF!
A9: 6 | B9: śr. | C9: =VLOOKUP("D",STYCZEŃ!J$2:$AJ$32,27,0) -> #REF!
A10: 7 | B10: czw. | C10: =VLOOKUP("D",STYCZEŃ!K$2:$AJ$32,26,0) -> #REF!
A11: 8 | B11: pt. | C11: =VLOOKUP("D",STYCZEŃ!L$2:$AJ$32,25,0) -> #REF! | D11: 20.00 - 08.00 SAJDAK
A12: 9 | B12: sob. | C12: =VLOOKUP("D",STYCZEŃ!M$2:$AJ$32,24,0) -> #REF!
A13: 10 | B13: niedz. | C13: =VLOOKUP("D",STYCZEŃ!N$2:$AJ$32,23,0) -> #REF!
A14: 11 | B14: pon. | C14: =VLOOKUP("D",STYCZEŃ!O$2:$AJ$32,22,0) -> #REF!
A15: 12 | B15: wt. | C15: =VLOOKUP("D",STYCZEŃ!P$2:$AJ$32,21,0) -> #REF!
A16: 13 | B16: śr. | C16: =VLOOKUP("D",STYCZEŃ!Q$2:$AJ$32,20,0) -> #REF!
A17: 14 | B17: czw. | C17: =VLOOKUP("D",STYCZEŃ!R$2:$AJ$32,19,0) -> #REF!
A18: 15 | B18: pt. | C18: =VLOOKUP("D",STYCZEŃ!S$2:$AJ$32,18,0) -> #REF!
A19: 16 | B19: sob. | C19: =VLOOKUP("D",STYCZEŃ!T$2:$AJ$32,17,0) -> #REF!
A20: 17 | B20: niedz. | C20: =VLOOKUP("D",STYCZEŃ!U$2:$AJ$32,16,0) -> #REF!
A21: 18 | B21: pon. | C21: =VLOOKUP("D",STYCZEŃ!V$2:$AJ$32,15,0) -> #REF!
A22: 19 | B22: wt. | C22: =VLOOKUP("D",STYCZEŃ!W$2:$AJ$32,14,0) -> #REF!
A23: 20 | B23: śr. | C23: =VLOOKUP("D",STYCZEŃ!X$2:$AJ$32,13,0) -> #REF!
A24: 21 | B24: czw. | C24: =VLOOKUP("D",STYCZEŃ!Y$2:$AJ$32,12,0) -> #REF!
A25: 22 | B25: pt. | C25: =VLOOKUP("D",STYCZEŃ!Z$2:$AJ$32,11,0) -> #REF!
A26: 23 | B26: sob. | C26: =VLOOKUP("D",STYCZEŃ!AA$2:$AJ$32,10,0) -> #REF!
A27: 24 | B27: niedz. | C27: =VLOOKUP("D",STYCZEŃ!AB$2:$AJ$32,9,0) -> #REF!
A28: 25 | B28: pon. | C28: =VLOOKUP("D",STYCZEŃ!AC$2:$AJ$32,8,0) -> #REF!
A29: 26 | B29: wt. | C29: =VLOOKUP("D",STYCZEŃ!AD$2:$AJ$32,7,0) -> #REF!
A30: 27 | B30: śr. | C30: =VLOOKUP("D",STYCZEŃ!AE$2:$AJ$32,6,0) -> #REF!
A31: 28 | B31: czw. | C31: =VLOOKUP("D",STYCZEŃ!AF$2:$AJ$32,5,0) -> #REF!
A32: 29 | B32: pt. | C32: =VLOOKUP("D",STYCZEŃ!AG$2:$AJ$32,4,0) -> #REF!
A33: 30 | B33: sob. | C33: =VLOOKUP("D",STYCZEŃ!AH$2:$AJ$32,3,0) -> #REF!
A34: 31 | B34: niedz. | C34: =VLOOKUP("D",STYCZEŃ!AI$2:$AJ$32,2,0) -> #N/A

Sheet LUTY
A1: SG | D1: 44228 | E1: 44228 | F1: 44229 | G1: 44230 | H1: 44231 | I1: 44232 | J1: 44233 | K1: 44234 | L1: 44235 | M1: 44236 | N1: 44237 | O1: 44238 | P1: 44239 | Q1: 44240 | R1: 44241 | S1: 44242 | T1: 44243 | U1: 44244 | V1: 44245 | W1: 44246 | X1: 44247 | Y1: 44248 | Z1: 44249 | AA1: 44250 | AB1: 44251 | AC1: 44252 | AD1: 44253 | AE1: 44254 | AF1: 44255 | AH1: =20*8 -> 160 | AI1: 44286 | AJ1: Służba | AK1: Dyżur | AL1: inne | AM1: DT | AN1: zwolnienia
A2: SG212 | B2: D | C2: BORZĘCKI Tomasz | D2: =STYCZEŃ!AK2+STYCZEŃ!D2 -> #REF! | I2: ps | J2: s | K2: s | L2: ps | M2: - | N2: - | O2: - | P2: - | S2: ps | T2: s | U2: s | V2: s | W2: s | X2: s | Y2: s | Z2: ps | AB2: ! | AE2: - | AF2: - | AG2: =_xlfn.CONCAT(#REF!,Tabela13[[#This Row],[FUNKCJONARIUSZ]]) -> #REF! | AH2: =AJ2+AK2+AL2-$AH$1+AM2+AN2+D2 -> #REF! | AI2: =MARZEC!AK2 -> #REF! | AJ2: =COUNTIF(E2:AF2,"D")*24+COUNTIF(E2:AF2,"12g")*12 -> 0 | AK2: =SUM(COUNTIF(E2:AF2,"k")+COUNTIF(E2:AF2,"s")+COUNTIF(E2:AF2,"wse"))*24+SUM(COUNTIF(E2:AF2,"Pk")+COUNTIF(E2:AF2,"Ps"))*12 -> 240 | AL2: =SUM(E2:AF2)+COUNTIF(E2:AF2,"uw")*8+COUNTIF(E2:AF2,"us")*8+COUNTIF(E2:AF2,"uz")*8 -> 0 | AM2: =COUNTIF(A2:AE2,"DT")*8 -> 0 | AN2: 0
A3: SG068 | B3: MP | C3: BUKOWSKI Bartosz | D3: =STYCZEŃ!AK3+STYCZEŃ!D3 -> #REF! | E3: uz | F3: uz | G3: uz | H3: uz | I3: uz | J3: - | K3: - | L3: uz | M3: uz | N3: uw | O3: uw | P3: uw | Q3: - | R3: - | S3: uw | T3: uw | U3: uw | V3: uw | W3: uw | X3: - | Y3: - | Z3: uw | AA3: uw | AG3: =_xlfn.CONCAT(#REF!,Tabela13[[#This Row],[FUNKCJONARIUSZ]]) -> #REF! | AH3: =AJ3+AK3+AL3-$AH$1+AM3+AN3+D3 -> #REF! | AI3: =MARZEC!AK3 -> #REF! | AJ3: =COUNTIF(E3:AF3,"D")*24+COUNTIF(E3:AF3,"12g")*12 -> 0 | AK3: =SUM(COUNTIF(E3:AF3,"k")+COUNTIF(E3:AF3,"s")+COUNTIF(E3:AF3,"wse"))*24+SUM(COUNTIF(E3:AF3,"Pk")+COUNTIF(E3:AF3,"Ps"))*12 -> 0 | AL3: =SUM(E3:AF3)+COUNTIF(E3:AF3,"uw")*8+COUNTIF(E3:AF3,"us")*8+COUNTIF(E3:AF3,"uz")*8 -> 136 | AM3: =COUNTIF(A3:AE3,"DT")*8 -> 0 | AN3: 0
A4: SG214 | B4: MP | C4: CHYŁA Katarzyna | D4: =STYCZEŃ!AK4+STYCZEŃ!D4 -> #REF! | S4: ps | T4: s | U4: s | V4: s | W4: s | X4: s | Y4: s | Z4: ps | AA4: - | AB4: - | AC4: - | AD4: - | AE4: - | AF4: - | AG4: =_xlfn.CONCAT(#REF!,Tabela13[[#This Row],[FUNKCJONARIUSZ]]) -> #REF! | AH4: =AJ4+AK4+AL4-$AH$1+AM4+AN4+D4 -> #REF! | AI4: =MARZEC!AK4 -> #REF! | AJ4: =COUNTIF(E4:AF4,"D")*24+COUNTIF(E4:AF4,"12g")*12 -> 0 | AK4: =SUM(COUNTIF(E4:AF4,"k")+COUNTIF(E4:AF4,"s")+COUNTIF(E4:AF4,"wse"))*24+SUM(COUNTIF(E4:AF4,"Pk")+COUNTIF(E4:AF4,"Ps"))*12 -> 168 | AL4: =SUM(E4:AF4)+COUNTIF(E4:AF4,"uw")*8+COUNTIF(E4:AF4,"us")*8+COUNTIF(E4:AF4,"uz")*8 -> 0 | AM4: =COUNTIF(A4:AE4,"DT")*8 -> 0 | AN4: 0
A5: SG068 | B5: MP | C5: DRGAS Kamil | D5: =STYCZEŃ!AK5+STYCZEŃ!D5 -> #REF! | L5: ps | M5: s | N5: s | O5: s | P5: s | Q5: s | R5: s | S5: ps | T5: - | U5: - | V5: - | W5: - | X5: - | Y5: - | Z5: - | AD5: d | AG5: =_xlfn.CONCAT(#REF!,Tabela13[[#This Row],[FUNKCJONARIUSZ]]) -> #REF! | AH5: =AJ5+AK5+AL5-$AH$1+AM5+AN5+D5 -> #REF! | AI5: =MARZEC!AK5 -> #REF! | AJ5: =COUNTIF(E5:AF5,"D")*24+COUNTIF(E5:AF5,"12g")*12 -> 24 | AK5: =SUM(COUNTIF(E5:AF5,"k")+COUNTIF(E5:AF5,"s")+COUNTIF(E5:AF5,"wse"))*24+SUM(COUNTIF(E5:AF5,"Pk")+COUNTIF(E5:AF5,"Ps"))*12 -> 168 | AL5: =SUM(E5:AF5)+COUNTIF(E5:AF5,"uw")*8+COUNTIF(E5:AF5,"us")*8+COUNTIF(E5:AF5,"uz")*8 -> 0 | AM5: =COUNTIF(A5:AE5,"DT")*8 -> 0 | AN5: 0 | AO5: D | AP5: służba | AQ5: 24
A6: SG214 | B6: M | C6: GĄSIEWSKI Dariusz | D6: =STYCZEŃ!AK6+STYCZEŃ!D6 -> #REF! | E6: ps | F6: - | G6: - | H6: - | I6: - | J6: - | K6: - | L6: - | M6: - | N6: - | O6: - | P6: - | Q6: - | R6: - | S6: - | T6: - | U6: - | V6: - | AG6: =_xlfn.CONCAT(#REF!,Tabela13[[#This Row],[FUNKCJONARIUSZ]]) -> #REF! | AH6: =AJ6+AK6+AL6-$AH$1+AM6+AN6+D6 -> #REF! | AI6: =MARZEC!AK6 -> #REF! | AJ6: =COUNTIF(E6:AF6,"D")*24+COUNTIF(E6:AF6,"12g")*12 -> 0 | AK6: =SUM(COUNTIF(E6:AF6,"k")+COUNTIF(E6:AF6,"s")+COUNTIF(E6:AF6,"wse"))*24+SUM(COUNTIF(E6:AF6,"Pk")+COUNTIF(E6:AF6,"Ps"))*12 -> 12 | AL6: =SUM(E6:AF6)+COUNTIF(E6:AF6,"uw")*8+COUNTIF(E6:AF6,"us")*8+COUNTIF(E6:AF6,"uz")*8 -> 0 | AM6: =COUNTIF(A6:AE6,"DT")*8 -> 0 | AN6: 0 | AO6: 12g | AP6: służba gazowiec | AQ6: 12
A7: SG214 | B7: D | C7: GRZESIAK Sebastian | D7: =STYCZEŃ!AK7+STYCZEŃ!D7 -> #REF! | H7: uz | I7: uz | J7: - | K7: - | P7: ps | Q7: s | R7: s | S7: ps | T7: uz | U7: uz | V7: uz | W7: uz | X7: - | AA7: ps | AB7: s | AC7: s | AD7: ps | AG7: =_xlfn.CONCAT(#REF!,Tabela13[[#This Row],[FUNKCJONARIUSZ]]) -> #REF! | AH7: =AJ7+AK7+AL7-$AH$1+AM7+AN7+D7 -> #REF! | AI7: =MARZEC!AK7 -> #REF! | AJ7: =COUNTIF(E7:AF7,"D")*24+COUNTIF(E7:AF7,"12g")*12 -> 0 | AK7: =SUM(COUNTIF(E7:AF7,"k")+COUNTIF(E7:AF7,"s")+COUNTIF(E7:AF7,"wse"))*24+SUM(COUNTIF(E7:AF7,"Pk")+COUNTIF(E7:AF7,"Ps"))*12 -> 144 | AL7: =SUM(E7:AF7)+COUNTIF(E7:AF7,"uw")*8+COUNTIF(E7:AF7,"us")*8+COUNTIF(E7:AF7,"uz")*8 -> 48 | AM7: =COUNTIF(A7:AE7,"DT")*8 -> 0 | AN7: 0 | AO7: ps | AP7: 1/2 dyżuru | AQ7: 12
A8: SG214 | B8: D | C8: JAKIMIAK Marcin | D8: =STYCZEŃ!AK8+STYCZEŃ!D8 -> #REF! | E8: ps | F8: s | G8: s | H8: s | I8: ps | J8: - | K8: - | L8: - | M8: - | S8: d | W8: uz | X8: - | Y8: - | Z8: uz | AA8: uz | AB8: uz | AD8: ps | AE8: s | AF8: s | AG8: =_xlfn.CONCAT(#REF!,Tabela13[[#This Row],[FUNKCJONARIUSZ]]) -> #REF! | AH8: =AJ8+AK8+AL8-$AH$1+AM8+AN8+D8 -> #REF! | AI8: =MARZEC!AK8 -> #REF! | AJ8: =COUNTIF(E8:AF8,"D")*24+COUNTIF(E8:AF8,"12g")*12 -> 24 | AK8: =SUM(COUNTIF(E8:AF8,"k")+COUNTIF(E8:AF8,"s")+COUNTIF(E8:AF8,"wse"))*24+SUM(COUNTIF(E8:AF8,"Pk")+COUNTIF(E8:AF8,"Ps"))*12 -> 156 | AL8: =SUM(E8:AF8)+COUNTIF(E8:AF8,"uw")*8+COUNTIF(E8:AF8,"us")*8+COUNTIF(E8:AF8,"uz")*8 -> 32 | AM8: =COUNTIF(A8:AE8,"DT")*8 -> 0 | AN8: 0 | AO8: s | AP8: dyżur Ś-cie | AQ8: 24
